Workbook

Sheet 2026
B2: POLITICA COMERCIAL GUARANI 2024
B5: versão 2026 1.1 | E5: VALOR DA HORA PROJETOS | F5: 180
E6: VALOR DA HORA MELHORIA | F6: 176
E7: VALOR DA HORA PARCEIRO | F7: 220
E8: CONDIÇÃO COMERCIAL | F8: ATÉ 6X SEM JUROS
C10: Obs.: | D10: Horasna base esta com 20% de desconto.
D12: VALOR | F12: VALOR UNITÁRIO
B13: PRODUTOS | C13: QTDE | D13: CDU/SETUP | E13: HORAS | F13: MENSALIDADE | G13: INFORMATIVO
B14: Guarani ERP | C14: 1 | D14: 275.62 | E14: projetada pelo setor de projetos | F14: 275.62 | G14: O valor da CDU, é multiplicar a mensalidade da propsota pelo fator 3.
B15: Guarani AFV* | C15: 1 | D15: 115 | E15: 80 | F15: 78.41 | G15: O valor da mensalidade de R$115,00 é o COMBO (Núcleo+Orç. WEB + Iara), podendo a chegar em R$105,00. O valor da CDU, é multiplicar a mensalidade da propsota pelo fator 3.
B16: Guarani B2B | C16: 1 | D16: =26200/2 -> 13100 | E16: setup configuração | F16: =3400/2 -> 1700 | G16: Lojas STANDARD, a customizada existe horas adicionais, minimo garantido 1900
B17: CNPJ Adicional | C17: 1 | D17: à definir | E17: 16 | F17: 0 | G17: O SETUP é o valor da mensalidade ERP atual do cliente
B19: OBSERVAÇÕES:
B20: *O valor unitário dependerá do cenário específico de cada cliente, pois é necessário dimensionar o número de usuários + plugins contratados. Utilize a calculadora de AFV para obter a mensalidade.
D23: VALOR | F23: VALOR UNITÁRIO
B24: ADICIONAIS DIRETO ERP | C24: QTDE | D24: CDU/SETUP | E24: HORAS | F24: MENSALIDADE | G24: INFORMATIVO
B25: Guarani BI | C25: 1 | D25: =16200/2 -> 8100 | E25: setup configuração | F25: =2160/2 -> 1080
B26: Guarani Cloud* | C26: 1 | D26: 1600 | E26: setup configuração | F26: 1753 | G26: Use a calculadora cloud para obter o valor da mensaldiade.
B27: MDe - Manifestação do Destinatário | C27: 1 | D27: 0 | E27: 16 | F27: 356.4
B28: Importação XML (Mercado Livre Full) | C28: 1 | D28: 0 | E28: 16 | F28: 356.4
B29: Telemarketing | C29: 1 | D29: 0 | E29: 24 | F29: 356.4
B30: MDFe - Manifestação Eletrônico de Documentos Fiscais | C30: 1 | D30: 0 | E30: 16 | F30: 356.4
B31: CTe- Conhecimento de Transporte Eletrônico | C31: 1 | D31: 0 | E31: 16 | F31: 356.4
B32: Envio de Boleto via Whatsapp | C32: 1 | D32: 0 | E32: 2 | F32: 356.4
B33: Qualidade | C33: 1 | D33: 0 | E33: projetada pelo setor de projetos | F33: 356.4
B34: CIAP / ATIVO IMOBILIZADO | C34: 1 | D34: 0 | E34: 16 | F34: 356.4
B35: Guarani Contábil | C35: 1 | D35: 0 | E35: projetada pelo setor de projetos | F35: 689.04
B36: Guarani PCP | C36: 1 | D36: à definir | E36: projetada pelo setor de projetos | F36: 0 | G36: Está embutido no preço da mensalidade do ERP
B37: Guarani Comex | C37: 1 | D37: 6000 | E37: 20 | F37: 2000
B38: Guarani FTP | C38: 1 | D38: 0 | E38: 2 | F38: 240
B39: Guarani WMS | C39: 1 | D39: 528 | E39: projetada pelo setor de projetos | F39: 142.56 | G39: Atualmetne a CDU está BONIFICADA
B41: OBSERVAÇÕES:
B42: *O valor mensal dependerá do cenário específico de cada cliente, pois é necessário dimensionar o número de usuários de acesso e tamanho de banco de dados. Utilize a calculadora de Cloud para obter a mensalidade.
D45: VALOR | F45: VALOR UNITÁRIO
B46: ADICIONAIS INDIRETO ERP | C46: QTDE | D46: CDU/SETUP | E46: HORAS | F46: MENSALIDADE | G46: INFORMATIVO
B47: Concil* | C47: 1 | D47: 0 | E47: 16 | F47: 712.8 | G47: Existe apresentação e negociação pelo parceiro de aliança
B48: Koncili* | C48: 1 | D48: 0 | E48: 16 | F48: 712.8 | G48: Existe apresentação e negociação pelo parceiro de aliança
B49: Routeasy* | C49: 1 | D49: 0 | E49: 16 | F49: 712.8 | G49: Existe apresentação e negociação pelo parceiro de aliança
B50: Link de Pagamento* | C50: 1 | D50: 0 | E50: 16 | F50: 712.8 | G50: Existe apresentação e negociação pelo parceiro de aliança
B51: SSW* | C51: 1 | D51: 0 | E51: 16 | F51: 712.8 | G51: Existe apresentação e negociação pelo parceiro de aliança
...

Sheet CalculadoraComissão
A1: CALCULADORA COMISSÃO PROJETO | L1: CALCULADORA COMISSÃO MELHORIA
C3: Hr Negociada | O3: Hr Negociada
C4: 169.78 | O4: 176
C5: =1-(C4/'2026'!$F$5) -> 0.056777778 | D5: Fator Desconto | O5: =1-(O4/'2026'!$F$6) -> 0 | P5: Fator Desconto
F6: Tabela 2. Base Comissão | R6: Tabela 2. Base Comissão Melhoria
F7: Desconto | G7: Comissão | H7: Valor HR | S7: Desconto | T7: Comissão | U7: Valor HR
B8: Valor Faixa Desconto | C8: Cálculo | D8: Informativo | F8: =0/100 -> 0 | G8: =7/100 -> 0.07 | H8: 180 | N8: Valor Faixa Desconto | O8: Cálculo | P8: Informativo | R8: 0 | S8: =0/100 -> 0 | T8: 0.01 | U8: 176
A9: Desconto Inicial | B9: 0 | C9: =C5*100 -> 5.6777778 | D9: Desconto | F9: 0.05 | G9: =5/100 -> 0.05 | H9: =H8-(H8*F9) -> 171 | M9: Desconto Inicial | N9: 0 | O9: =O5*100 -> 0 | P9: Desconto | R9: 0.1 | S9: 0.1 | T9: 0.007 | U9: =U8-(U8*S9) -> 158.4
A10: Desconto Final | B10: 8 | C10: =IF(C9<=5,(C9-F8)/(B10-B9), IF(AND(C9>5,C9<=8),(C9-F9)/(B10-B9), IF(AND(C9>8,C9<=12),(C9-F10)/(B10-B9), "Procure seu Gestor"))) -> 0.70347222 | D10: Cálculo Desconto | F10: 0.08 | G10: =3/100 -> 0.03 | H10: =H8-(H8*F10) -> 165.6 | M10: Desconto Final | N10: 20 | O10: =IF(O9<=10,(O9-R8)/(N10-N9), IF(AND(O9>10,O9<=20),(O9-R9)/(N10-N9), IF(AND(O9>20,O9<=30),(O9-R10)/(N10-N9), "Procure seu Gestor"))) -> 0 | P10: Cálculo Desconto | R10: 0.2 | S10: 0.2 | T10: 0.005 | U10: =U8-(U8*S10) -> 140.8
B11: Valor Faixa de Comissão | C11: Cálculo | D11: Informativo | F11: 0.12 | G11: =1/100 -> 0.01 | H11: =H8-(H8*F11) -> 158.4 | N11: Valor Faixa de Comissão | O11: Cálculo | P11: Informativo | R11: 0.3 | S11: 0.3 | T11: 0.0025 | U11: =U8-(U8*S11) -> 123.2
B12: 5 | F12: >12%, e até 20% com autorização do GESTOR e mantém comissão de 0,5% | N12: 1 | R12: >30%, com autorização do GESTOR e mantém comissão de 0,25%
B13: 3 | C13: =B13-B12 -> -2 | D13: Cálculo Comissão | N13: 0.5 | O13: =N13-N12 -> -0.5 | P13: Cálculo Comissão
A19: Fator final comissão | C19: =IFERROR(B12+(C10*C13),"Procure seu Gestor") -> 3.5930556 | D19: Em percentual | M19: Fator final comissão | O19: =IFERROR(N12+(O10*O13),"Procure seu Gestor") -> 1 | P19: Em percentual

Sheet Cloud ICUS 
A1: CLOUD ICUS
A3: TABELA REFERÊNCIA | G3: VALOR A LANÇAR NA PROPOSTA | O3: Faixas do Guarani Cloud
A4: PRODUTO | B4: QTDE | C4: VALOR UNITÁRIO | D4: DESCONTO | E4: VALOR TOTAL MENSAL | G4: FATOR | H4: IRACEMA | I4: 5 | J4: Pode Chegar | K4: Proposta Atual | O4: De 1 até 10 licenças → | P4: Mensalidade: | Q4: 2524.72
A5: SERVIDORES: 1 - Empresas até 10 licenças | B5: 1 | C5: 1434.5 | D5: 286.9 | E5: =C5-D5 -> 1147.6 | G5: 2.2 | H5: De 1 até 10 licenças → | I5: Mensalidade: | J5: =E5 -> 1147.6 | K5: =G5*J5 -> 2524.72 | L5: =IF($I$4<11,"USE ESSE VALOR","OUTRA FAIXA") -> USE ESSE VALOR | O5: De 11 até 23 licenças → | P5: Mensalidade: | Q5: 3844.54
A6: SERVIDORES: 2 - Empresa até 23 licenças | B6: 1 | C6: 2184.4 | D6: 436.88 | E6: =C6-D6 -> 1747.52 | G6: 2.2 | H6: De 11 até 23 licenças → | I6: Mensalidade: | J6: =E6 -> 1747.52 | K6: =G6*J6 -> 3844.544 | L6: {=IF(K15I4>10,IF(I4<24,"USE ESSE VALOR"),"OUTRA FAIXA"),IF(I4>24,"OUTRA FAIXA")} -> #NAME? | O6: De 24 até 47 licenças → | P6: Mensalidade: | Q6: 6308.9
A7: SERVIDORES: 3 - Empresas até 47 licenças | B7: 1 | C7: 3584.6 | D7: 716.92 | E7: =C7-D7 -> 2867.68 | G7: 2.2 | H7: De 24 até 47 licenças → | I7: Mensalidade: | J7: =E7 -> 2867.68 | K7: =G7*J7 -> 6308.896 | L7: =IF(I4>=24,"USE ESSE VALOR","OUTRA FAIXA") -> OUTRA FAIXA | O7: Observação: o valor da mensalidade será definido conforme a faixa de licenças em que o cliente se enquadrar.
H8: Observação: o valor da mensalidade será definido conforme a faixa de licenças em que o cliente se enquadrar.
D9: QTDE
A10: SERVIDORES: 0 - Empresas até 5 licenças | B10: 1 | C10: 130 | D10: 5 | E10: =C10*D10 -> 650 | G10: 2.2 | H10: =E10*G10 -> 1430

Sheet Cloud ICUS - Ref
A1: CLOUD ICUS
A3: PRODUTO | B3: QTDE | C3: VALOR UNITÁRIO | D3: DESCONTO | E3: VALOR TOTAL MENSAL | G3: FATOR | H3: UNIVENDAS | J3: Pode Chegar | K3: Proposta Atual
A4: SERVIDORES: 1 - Empresas até 10 licenças | B4: 1 | C4: 1434.5 | D4: 286.9 | E4: =C4-D4 -> 1147.6 | G4: 2.2 | H4: De 1 até 10 licenças → | I4: Mensalidade: | J4: =E4*G4 -> 2524.72 | K4: 3098.52
A5: SERVIDORES: 2 - Empresa até 23 licenças | B5: 1 | C5: 2184.4 | D5: 436.88 | E5: =C5-D5 -> 1747.52 | G5: 2.2 | H5: De 11 até 23 licenças → | I5: Mensalidade: | J5: =E5*G5 -> 3844.544 | K5: 4718.304
A6: SERVIDORES: 3 - Empresas até 47 licenças | B6: 1 | C6: 3584.6 | D6: 716.92 | E6: =C6-D6 -> 2867.68 | G6: 2.2 | H6: De 24 até 47 licenças → | I6: Mensalidade: | J6: =E6*G6 -> 6308.896 | K6: 7742.736
H7: Observação: o valor da mensalidade será definido conforme a faixa de licenças em que o cliente se enquadrar.
A9: PRODUTO | B9: QTDE | C9: VALOR UNITÁRIO | D9: DESCONTO | E9: VALOR TOTAL MENSAL | G9: 12 Licenças ERP + 3 PDV
A10: SERVIDORES: 1 - Empresas até 10 licenças | B10: 1 | C10: 1434.5 | D10: 286.9 | E10: =C10-D10 -> 1147.6 | G10: FATOR | H10: PLASTCAP | J10: ICUS | K10: Proposta Atual
A11: SERVIDORES: 2 - Empresa até 23 licenças | B11: 1 | C11: 2184.4 | D11: 436.88 | E11: =C11-D11 -> 1747.52 | G11: 2.2 | H11: De 1 até 10 licenças → | I11: Mensalidade: | J11: =E10 -> 1147.6 | K11: =E10*G11 -> 2524.72
A12: SERVIDORES: 3 - Empresas até 47 licenças | B12: 1 | C12: 3584.6 | D12: 716.92 | E12: =C12-D12 -> 2867.68 | G12: 2.2 | H12: De 11 até 23 licenças → | I12: Mensalidade: | J12: =E11 -> 1747.52 | K12: =E11*G12 -> 3844.544
G13: 2.2 | H13: De 24 até 47 licenças → | I13: Mensalidade: | J13: =E12 -> 2867.68 | K13: =E12*G13 -> 6308.896
H14: Observação: o valor da mensalidade será definido conforme a faixa de licenças em que o cliente se enquadrar.
A16: PRODUTO | B16: QTDE | C16: VALOR UNITÁRIO | D16: DESCONTO | E16: VALOR TOTAL MENSAL | G16: 15 Licenças ERP
A17: SERVIDORES: 1 - Empresas até 10 licenças | B17: 1 | C17: 1434.5 | D17: 286.9 | E17: =C17-D17 -> 1147.6 | G17: FATOR | H17: HAI IMPORT | J17: ICUS | K17: Proposta Atual
A18: SERVIDORES: 2 - Empresa até 23 licenças | B18: 1 | C18: 2184.4 | D18: 436.88 | E18: =C18-D18 -> 1747.52 | G18: 2.2 | H18: De 1 até 10 licenças → | I18: Mensalidade: | J18: =E17 -> 1147.6 | K18: =E17*G18 -> 2524.72
A19: SERVIDORES: 3 - Empresas até 47 licenças | B19: 1 | C19: 3584.6 | D19: 716.92 | E19: =C19-D19 -> 2867.68 | G19: 2.2 | H19: De 11 até 23 licenças → | I19: Mensalidade: | J19: =E18 -> 1747.52 | K19: =E18*G19 -> 3844.544
G20: 2.2 | H20: De 24 até 47 licenças → | I20: Mensalidade: | J20: =E19 -> 2867.68 | K20: =E19*G20 -> 6308.896
H21: Observação: o valor da mensalidade será definido conforme a faixa de licenças em que o cliente se enquadrar.
A23: PRODUTO | B23: QTDE | C23: VALOR UNITÁRIO | D23: DESCONTO | E23: VALOR TOTAL MENSAL | G23: 42 Licenças ERP
A24: SERVIDORES: 1 - Empresas até 10 licenças | B24: 1 | C24: 1434.5 | D24: 286.9 | E24: =C24-D24 -> 1147.6 | G24: FATOR | H24: BELA FLOR | J24: ICUS | K24: Proposta Atual
A25: SERVIDORES: 2 - Empresa até 23 licenças | B25: 1 | C25: 2184.4 | D25: 436.88 | E25: =C25-D25 -> 1747.52 | G25: 2.2 | H25: De 1 até 10 licenças → | I25: Mensalidade: | J25: =E24 -> 1147.6 | K25: =E24*G25 -> 2524.72
A26: SERVIDORES: 3 - Empresas até 47 licenças | B26: 1 | C26: 3584.6 | D26: 716.92 | E26: =C26-D26 -> 2867.68 | G26: 2.2 | H26: De 11 até 23 licenças → | I26: Mensalidade: | J26: =E25 -> 1747.52 | K26: =E25*G26 -> 3844.544
G27: 2.2 | H27: De 24 até 47 licenças → | I27: Mensalidade: | J27: =E26 -> 2867.68 | K27: =E26*G27 -> 6308.896
H28: Observação: o valor da mensalidade será definido conforme a faixa de licenças em que o cliente se enquadrar.
A30: PRODUTO | B30: QTDE | C30: VALOR UNITÁRIO | D30: DESCONTO | E30: VALOR TOTAL MENSAL | G30: 18 Licenças ERP
A31: SERVIDORES: 1 - Empresas até 10 licenças | B31: 1 | C31: 1434.5 | D31: 286.9 | E31: =C31-D31 -> 1147.6 | G31: FATOR | H31: VALPORT | J31: ICUS | K31: Proposta Atual
A32: SERVIDORES: 2 - Empresa até 23 licenças | B32: 1 | C32: 2184.4 | D32: 436.88 | E32: =C32-D32 -> 1747.52 | G32: 2.2 | H32: De 1 até 10 licenças → | I32: Mensalidade: | J32: =E31 -> 1147.6 | K32: =E31*G32 -> 2524.72
A33: SERVIDORES: 3 - Empresas até 47 licenças | B33: 1 | C33: 3584.6 | D33: 716.92 | E33: =C33-D33 -> 2867.68 | G33: 2.2 | H33: De 11 até 23 licenças → | I33: Mensalidade: | J33: =E32 -> 1747.52 | K33: =E32*G33 -> 3844.544
G34: 2.2 | H34: De 24 até 47 licenças → | I34: Mensalidade: | J34: =E33 -> 2867.68 | K34: =E33*G34 -> 6308.896
H35: Observação: o valor da mensalidade será definido conforme a faixa de licenças em que o cliente se enquadrar.
A37: PRODUTO | B37: QTDE | C37: VALOR UNITÁRIO | D37: DESCONTO | E37: VALOR TOTAL MENSAL | G37: 5 Licenças ERP
A38: SERVIDORES: 1 - Empresas até 10 licenças | B38: 1 | C38: 1434.5 | D38: 286.9 | E38: =C38-D38 -> 1147.6 | G38: FATOR | H38: VIC IMPORT | J38: ICUS | K38: Proposta Atual
A39: SERVIDORES: 2 - Empresa até 23 licenças | B39: 1 | C39: 2184.4 | D39: 436.88 | E39: =C39-D39 -> 1747.52 | G39: 2.2 | H39: De 1 até 10 licenças → | I39: Mensalidade: | J39: =E38 -> 1147.6 | K39: =E38*G39 -> 2524.72
A40: SERVIDORES: 3 - Empresas até 47 licenças | B40: 1 | C40: 3584.6 | D40: 716.92 | E40: =C40-D40 -> 2867.68 | G40: 2.2 | H40: De 11 até 23 licenças → | I40: Mensalidade: | J40: =E39 -> 1747.52 | K40: =E39*G40 -> 3844.544
G41: 2.2 | H41: De 24 até 47 licenças → | I41: Mensalidade: | J41: =E40 -> 2867.68 | K41: =E40*G41 -> 6308.896
H42: Observação: o valor da mensalidade será definido conforme a faixa de licenças em que o cliente se enquadrar.
A44: PRODUTO | B44: QTDE | C44: VALOR UNITÁRIO | D44: DESCONTO | E44: VALOR TOTAL MENSAL | G44: 12 Licenças ERP
A45: SERVIDORES: 1 - Empresas até 10 licenças | B45: 1 | C45: 1434.5 | D45: 286.9 | E45: =C45-D45 -> 1147.6 | G45: FATOR | H45: NVT IMPORT | J45: ICUS | K45: Proposta Atual
A46: SERVIDORES: 2 - Empresa até 23 licenças | B46: 1 | C46: 2184.4 | D46: 436.88 | E46: =C46-D46 -> 1747.52 | G46: 2.2 | H46: De 1 até 10 licenças → | I46: Mensalidade: | J46: =E45 -> 1147.6 | K46: =E45*G46 -> 2524.72
A47: SERVIDORES: 3 - Empresas até 47 licenças | B47: 1 | C47: 3584.6 | D47: 716.92 | E47: =C47-D47 -> 2867.68 | G47: 2.2 | H47: De 11 até 23 licenças → | I47: Mensalidade: | J47: =E46 -> 1747.52 | K47: =E46*G47 -> 3844.544
...

Sheet CalculadoraCloud
A1: CALCULADORA CLOUD | AR1: Tabela 1.4
B2: Quantidade | C2: Periodo | D2: Valor Custo R$ | E2: Fator | F2: Valor Venda R$ | AR2: Usuarios | AS2: Gb Maquina | AU2: Cloudlet | AV2: Gb | AW2: Ghz | AX2: Maquina basica Linux Gb | AY2: Maquina Basica Windows Gb | AZ2: Necessidade Gb Maquina Usuarios | BA2: Maquina W Gb RAM | BB2: Hd Windows Gb | BC2: Hd Linux Gb | BD2: IP Publico | BE2: TS
A3: Numero Usuarios | B3: 6 | AR3: 1 | AS3: 0.256 | AT3: RAM | AU3: 128 | AV3: =AU3/1024 -> 0.125 | AX3: 1 | AY3: 4 | AZ3: =B3*AS3 -> 1.536 | BA3: =AY3+AZ3 -> 5.536 | BB3: 30 | BC3: =B4 -> 60 | BE3: 32
A4: Tamanho do Banco (Gb) | B4: 60 | C4: Verifique o tamanho do bano junto ao cliente | AX4: =AX3/AV3 -> 8 | BA4: =BA3/AV3 -> 44.288
AX5: =AX4*0.013 -> 0.104 | BA5: =BA4*0.012 -> 0.531456
AX6: =AX5*24 -> 2.496 | BA6: =BA5*24 -> 12.754944
A7: Total Custo Maquinas | C7: Mês | D7: =AX7+BA7+BB7+BC7+BD7 -> 543.66832 | E7: 2 | F7: =D7*E7 -> 1087.3366 | AX7: =AX6*30 -> 74.88 | BA7: =BA6*30 -> 382.64832 | BB7: =BB3*Apoio!N2 -> 21.9 | BC7: =BC3*Apoio!N2 -> 43.8 | BD7: =Apoio!T2 -> 20.44 | BE7: =B3*BE3 -> 192
A8: Licenças TS | C8: Mês | D8: =BE7 -> 192 | E8: 2 | F8: =D8*E8 -> 384 | AR8: Referência 5 usuários e banco de 60 GB | AW8: Máquina | AX8: =AX7+BA7+BB7+BC7+BD7 -> 543.66832
A9: Storage BackUp | C9: Mês | D9: =Apoio!F27 -> 35.8 | E9: 2 | F9: =D9*E9 -> 71.6 | AW9: TS | AX9: =BE7 -> 192
A10: Total | C10: Mês | D10: =D8+D7+D9 -> 771.46832 | F10: =SUM(F7:F9) -> 1542.9366 | J10: sagol | AW10: Storage | AX10: =Apoio!F27 -> 35.8
E11: Aqui manter meu fator em 2.4 | I11: 1 | J11: 1371 | AW11: Preço de Custo | AX11: =SUM(AX8:AX10) -> 771.46832
H12: 12 | I12: 52 | J12: =H12*I12 -> 624
A13: Estrutura | D13: =D7+D9 -> 579.46832 | F13: 1747.52 | G13: univendas | J13: =J11+J12 -> 1995
F14: 2.7 | G14: fator
A15: Maquina Linux Servidor BD Firebird | F15: =F13*F14 -> 4718.304 | G15: Guarnai Cloud
A16: Maquina W Servidor Aplicação Guarani | G16: *23 Licenças TS
A18: PROPOSTA - CONDIÇÕES COMERCIAIS
G20: Desconto usado
A21: MARGEM DE DESCONTO 15% | G21: 0
J22: 1714.09
A23: SETUP | G23: 1600 | J23: 624
J24: =J22+J23 -> 2338.09
A25: MENSALIDADE | C25: QTDE | F25: VLR UNI | G25: TOTAL | J25: =J24-G29 -> 795.15336
A26: Guarani Cloud | C26: 1 | E26: 1 | F26: =G26/C26 -> 1158.9366 | G26: =F7+F9 -> 1158.9366 | J26: =J24-J25 -> 1542.9366
A27: Licenças de acesso ao Guarani Cloud | C27: =B3 -> 6 | E27: =B3 -> 6 | F27: =G27/C27 -> 64 | G27: =F8 -> 384
F28: Valor Bruto | G28: =G26+G27 -> 1542.9366
F29: Valor com Desconto | G29: =IF(G21>15%,"DESCONTO NÃO PERMITIDO",(IF($G$21<>"",($G$26+$G$27)-(($G$26+$G$27)*$G$21)))) -> 1542.9366
F30: Desconto R$ | G30: =G28-G29 -> 0

Sheet CalculadoraAFV
A1: CALCULADORA AFV
A3: TABELA REGRESSIVA AFV | D3: % | F3: PLUGIN | I3: %
A4: 20 | C4: 78.41 | D4: 0 | F4: Produto | G4: B2B | I4: =IF(G4=K6,O6,IF(G4=K7,O7,IF(G4=K8,O8,IF(G4=K9,O9,IF(G4=K10,O10,IF(G4=K11,O11,IF(G4=K12,O12,"ERRO"))))))) -> 35
A5: 21 | B5: 40 | C5: =C4-(($C$4)*0.05) -> 74.4895 | F5: 20 | H5: =I4 -> 35 | I5: 0 | K5: Add on - 2021 (10%)
A6: 41 | B6: 60 | C6: =C5-(($C$4)*0.05) -> 70.569 | F6: 21 | G6: 40 | H6: =H5-(($H$5)*0.05) -> 33.25 | K6: Pesquisa de mercado (Coleta + Quiz) | O6: 11
A7: 61 | B7: 80 | C7: =C6-(($C$4)*0.05) -> 66.6485 | F7: 41 | G7: 60 | H7: =H6-(($H$5)*0.05) -> 31.5 | K7: Orçamento WEB | O7: 19.8
A8: 81 | B8: 100 | C8: =C7-(($C$4)*0.05) -> 62.728 | F8: 61 | G8: 80 | H8: =H7-(($H$5)*0.05) -> 29.75 | K8: Agenda / Roteiro de visitas | O8: 16.5
A9: 101 | B9: 120 | C9: =C8-(($C$4)*0.05) -> 58.8075 | F9: 81 | G9: 100 | H9: =H8-(($H$5)*0.05) -> 28 | K9: Iara | O9: 19.8
A10: 121 | B10: 140 | C10: =C9-(($C$4)*0.05) -> 54.887 | F10: 101 | G10: 120 | H10: =H9-(($H$5)*0.05) -> 26.25 | K10: Multilojas | O10: 8.8
A11: 141 | B11: 160 | C11: =C10-(($C$4)*0.05) -> 50.9665 | F11: 121 | G11: 140 | H11: =H10-(($H$5)*0.05) -> 24.5 | K11: B2B | O11: 35
A12: 161 | B12: 180 | C12: =C11-(($C$4)*0.05) -> 47.046 | F12: 141 | G12: 160 | H12: =H11-(($H$5)*0.05) -> 22.75 | K12: Propsota Web | O12: 19.8
A13: 181 | B13: 200 | C13: =C12-(($C$4)*0.05) -> 43.1255 | F13: 161 | G13: 180 | H13: =H12-(($H$5)*0.05) -> 21
A14: >200 | C14: =C13-(($C$4)*0.05) -> 39.205 | D14: =C14/C4 -> 0.5 | F14: 181 | G14: 200 | H14: =H13-(($H$5)*0.05) -> 19.25
A15: Sem plugin | F15: >200 | H15: =H14-(($H$5)*0.05) -> 17.5 | I15: =H15/H5 -> 0.5

Sheet Descritivo Produtos
A1: DESCRITIVOS DOS PRODUTOS

Sheet Gatilhos de Contrato

Sheet Regras
A1: REGRAS | G1: METAS VENDEDOR
A2: Negociaçõs que envolve Fábio: | G2: Time | H2: 3 | I2: vendedor
A3: 1. Vendedor fez a venda sozinho 100% da comissão vendedor; | G3: Meta Recorrente | H3: 10000 | I3: por vendedor
A4: 2. Fábio, fez a apresentação, vendedor fica com 75% da comissão; | G4: Meta Projeto Horas | H4: 90000 | I4: por vendedor
A5: 3. Fábio, fez a negociação, vendedor fica com 50% da comissão; | G5: Proposta | H5: 15 | I5: não acumulativa
A6: 4. Diferente dos itens acima, vendedor fica com 25% da comissão. | G6: Apresentação | H6: 12 | I6: não acumulativa
G7: Meta Individual | H7: 10000
A8: Valores | G8: Meta Equipe | H8: 30000
A9: 1. O Valor da hora padrão, dentro do ano de 2024 é de R$180,00 reais.
A10: 2. A comissão dos vendedores estabeleciada acima, tem validade dentro do ano de 2024.
G11: METAS SDR
A12: Adicional de licença | G12: Time | H12: 2 | I12: SDR
A13: 1. Solicitação de licenças via e-mail, ligação ou whatsapp não terá comissão. | G13: Venda de Agendas | H13: 16 | I13: por SDR
A14: Obs.: Porém, vendedor visitou cliente ou está negociando outros módulos,treinamentos e conseguiu vender licenças a empresa pagará a comissão nortmalmente. | G14: Suspect | H14: 150 | I14: por SDR
G15: Atividades | H15: 70 | I15: por SDR por dia
A16: Projeto de ERP
A17: 1. Todo projeto de ERP, no momento de formatar a quantidade de horas, o VENDEDOR deve procurar o gerente de projetos, no momento o Fernando.
A19: Projeto de AFV
A20: 1. Novos projetos de AFV, o pacote de horas é 80 horas.
A22: Politica de Comissão Vendedor
A23: Horas de qualquer espécie: Comissão de 1% a 7%.
A24: Comissão de 100% da primeira mensalidade
A25: Bônus e Ônus, sobre o recorrente. Cobriu a META + 10%; Cobriu a META Equipe + 10% ; Não Cobriu a META - 10%
A27: Politica de Comissão SDR
A28: Converteu o projeto indicado pelo SDR, 5% da 1ª mensalidade
A29: Atingiu a meta de agendamento, 20% do salário
A30: Porém, 2 leads não qualificados mensais apontado pelo vendedor/closer e confirmado pelo gestor, perde toda a váriável do mês.
... A46: 25% de comissão sobre a CDU

Sheet Informativo Gestor
A1: INFORMATIVO GESTOR
A3: GUARANI BI | B3: A mensalidade pode ser ajustada dependendo o perfil do clinete, P=1500,00 M=1800; G=2160
A4: GUARANI B2B - CENÁRIO STANDARD | B4: 1. Instalação, integração e treinamento do integrador; 2. Treinamento da configuração das regras comerciais no cockpit de integração; 3. Construção da loja na AWS; 4. Carga de dados; 5. Configuração da loja no tema padrão; 6. Teste de homologação; 7. Configuração e treinamento para importar pedidos 8. Meios de pagamentos, contratação;
A5: HUB ECOMMERCE | B5: 1. Danfe simplificada; 2. Etiqueta de despacho; 3. Configuração fiscal p/ consumidor; 4. Emissão do pagamento do difal; 5. Cadastro e configuração dos market place ; 6. Instalação e configuração do hub (plugg to ou tray); 7. Recepção dos pedidos; 8. Conciliação bancária manual
A6: LINK DE PAGAMENTO | B6: Atualmente temos integração com SAFRA e VISA
A7: ADICIONAIS ERP | B7: Etapas refinar com o Fernando, a fazer.
A8: MODULO A ADICIONAR | B8: 1. VORTICE 2. RD STATION 3. PDV GUARANI

Sheet PDV Marcelo
C3: TABELA DE PREÇO PDV MARCELO
M4: SIMULAÇÃO - ENTREVISTA COM CLIENTE
C5: VIA API - CONFIGURAÇÃO DA ESTRUTURA DE HOSPEDAGEM EM UNVEM
M6: Qtde de Lojas? | N6: 10
C7: ADESÃO | M7: Número de CNPJ Matriz? | N7: 1
C8: ESTRUTURA NUVEM | D8: QTDE | E8: FAIXA DE VALOR | M8: Número de CNPJ Filial? | N8: 9
C9: LOJA MATRIZ (CNPJ) | D9: 1 | E9: 290 | M9: Número de PDV ? | N9: =N6*3 -> 30
C10: LOJA FILIAL (CNPJ) | D10: 1 | E10: 190 | M10: Número ADM Server Loja? | N10: 10
C11: PDV (PONTO DE VENDA) | D11: 1 | E11: 770 | F11: 690 | G11: 490 | H11: 410
C12: COMISSÃO GUARANI | E12: 0.4 | F12: 0.3 | G12: 0.15 | H12: 0.1
M13: ADESÃO - CONFIGURAÇÃO DA ESTRUTURA DE HOSPEDAGEM EM UNVEM | N13: QTDE | O13: VLR | P13: TOTAL
C14: MENSALIDADE/MANUTENÇÃO | M14: LOJA MATRIZ (CNPJ) | N14: 1 | O14: 290 | P14: =N14*O14 -> 290
C15: PDV (ADM SERVER LOJA) | D15: 1 | E15: 190 | M15: LOJA FILIAL (CNPJ) | N15: 9 | O15: 190 | P15: =N15*O15 -> 1710
C16: PDV (PONTO DE VENDA) | D16: 1 | E16: 280 | F16: 225 | G16: 200 | H16: 175 | M16: PDV (PONTO DE VENDA) | N16: 30 | O16: 770 | P16: =N16*O16 -> 23100
C17: COMISSÃO GUARANI | E17: 0.4 | F17: 0.3 | G17: 0.15 | H17: 0.1 | P17: =SUM(P14:P16) -> 25100
M19: MENSALIDADE | N19: QTDE | O19: VLR | P19: TOTAL
M20: PDV (ADM SERVER LOJA) | N20: 10 | O20: 190 | P20: =N20*O20 -> 1900
M21: PDV (PONTO DE VENDA) | N21: 30 | O21: 280 | P21: =N21*O21 -> 8400
C22: TABELA DE PREÇO PDV MARCELO | P22: =SUM(P20:P21) -> 10300
C24: VIA FTP
C26: ADESÃO
C27: ESTRUTURA NUVEM | D27: QTDE | E27: FAIXA DE VALOR | M27: GURANI ERP | N27: QTDE | O27: VLR | P27: TOTAL
C28: LOJA MATRIZ (CNPJ) | D28: 1 | E28: 900 | M28: INSTALAÇÃO/TREINAMENTO | N28: =7*10 -> 70 | O28: 180 | P28: =N28*O28 -> 12600
C29: LOJA FILIAL (CNPJ) | D29: 1 | E29: 450 | M29: MENSALIDADE | N29: 6 | O29: 275.62 | P29: =N29*O29 -> 1653.72
C30: PDV (PONTO DE VENDA) | D30: 1 | E30: 770 | F30: 690 | G30: 490 | H30: 410
C31: COMISSÃO | E31: 0.4 | F31: 0.3 | G31: 0.15 | H31: 0.1
C33: MENSALIDADE/MANUTENÇÃO | M33: RESUMO PROJETO
C34: PDV (ADM SERVER MATRIZ) | D34: 1 | E34: 190
C35: PDV (PONTO DE VENDA) | D35: 1 | E35: 280 | F35: 225 | G35: 200 | H35: 175 | M35: ADESÃO - CONFIGURAÇÃO DA ESTRUTURA DE HOSPEDAGEM EM UNVEM | N35: QTDE | O35: VLR | P35: TOTAL
C36: COMISSÃO | E36: 0.4 | F36: 0.3 | G36: 0.15 | H36: 0.1 | M36: GUARANI ERP | N36: 6 | O36: 1400 | P36: BONIFICADO
M37: LOJA MATRIZ (CNPJ) | N37: 1 | O37: 290 | P37: =N37*O37 -> 290
B38: Obs.: | C38: No caso de FTP, existe margem para negociar a adesão dentro da faixa acima apresentada. | M38: LOJA FILIAL (CNPJ) | N38: 9 | O38: 190 | P38: =N38*O38 -> 1710
M39: PDV (PONTO DE VENDA) | N39: 30 | O39: 770 | P39: =N39*O39 -> 23100
P40: =P37+P38+P39 -> 25100
M42: INSTALAÇÃO/TREINAMENTO | N42: QTDE | O42: VLR | P42: TOTAL
M43: GUARANI ERP | N43: 70 | O43: 180 | P43: =N43*O43 -> 12600
P44: =P43 -> 12600
M46: MENSALIDADE | N46: QTDE | O46: VLR | P46: TOTAL
M47: GUARANI ERP | N47: 6 | O47: 275.62 | P47: =N47*O47 -> 1653.72
M48: PDV (ADM SERVER LOJA) | N48: 10 | O48: 190 | P48: =N48*O48 -> 1900
...

Sheet Apoio
B2: Cloudlet | C2: = | D2: 128 | E2: Mb RAM | F2: 400 | G2: Mhz CPU | K2: Disco | L2: 0.001 | M2: R$ por GB/h | N2: 0.73 | O2: R$ GB/Mês | P2: Trafego | Q2: 0.24 | R2: R$ Por GB/Mês | S2: IP Publico | T2: 20.44 | U2: IP / Mês
B3: Faixa Cloudlet | H3: Reservados R$ | I3: Dinâmico R$
B4: 1 | C4: 4 | D4: =C4*D2 -> 512 | E4: Mb RAM | F4: =C4*F2 -> 1600 | G4: Mhz CPU | H4: 0.02 | I4: 0.02 | K4: 30 | L4: =K4*L2 -> 0.03 | M4: R$ por GB/h | N4: =K4*N2 -> 21.9 | O4: R$ GB/Mês | P4: 30 | Q4: =P4*Q2 -> 7.2 | R4: R$ Por GB/Mês | S4: 1 | T4: =S4*T2 -> 20.44 | U4: IP / Mês
B5: 5 | C5: 14 | D5: =C5*D2 -> 1792 | E5: Mb RAM | F5: =C5*F2 -> 5600 | G5: Mhz CPU | H5: 0.013 | I5: 0.014 | K5: 50 | L5: =K5*L2 -> 0.05 | M5: R$ por GB/h | N5: =K5*N2 -> 36.5 | O5: R$ GB/Mês | P5: 50 | Q5: =P5*Q2 -> 12 | R5: R$ Por GB/Mês | S5: 2 | T5: =S5*T2 -> 40.88 | U5: IP / Mês
B6: 15 | C6: 30 | D6: =C6*D2 -> 3840 | E6: Mb RAM | F6: =C6*F2 -> 12000 | G6: Mhz CPU | H6: 0.012 | I6: 0.013 | K6: 100 | L6: =K6*L2 -> 0.1 | M6: R$ por GB/h | N6: =K6*N2 -> 73 | O6: R$ GB/Mês | P6: 100 | Q6: =P6*Q2 -> 24 | R6: R$ Por GB/Mês
C7: CloudLet | D7: Gb RAM | F7: Ghz CPU | G7: Core | H7: p/ Hora | I7: p/dia | J7: p/mês
C8: 8 | D8: =(C8*$D$2)/1024 -> 1 | F8: =(C8*$F$2) -> 3200 | G8: 1 | H8: =C8*H4 -> 0.16 | I8: =H8*24 -> 3.84 | J8: =I8*30 -> 115.2
C9: =C8*2 -> 16 | D9: =(C9*$D$2)/1024 -> 2 | F9: =(C9*$F$2) -> 6400 | G9: 2 | H9: =C9*H5 -> 0.208 | I9: =H9*24 -> 4.992 | J9: =I9*30 -> 149.76
C10: =C9*2 -> 32 | D10: =(C10*$D$2)/1024 -> 4 | F10: =(C10*$F$2) -> 12800 | G10: 4 | H10: =C10*H6 -> 0.384 | I10: =H10*24 -> 9.216 | J10: =I10*30 -> 276.48
C11: =C10*2 -> 64 | D11: =(C11*$D$2)/1024 -> 8 | F11: =(C11*$F$2) -> 25600 | G11: 8 | H11: =C11*H6 -> 0.768 | I11: =H11*24 -> 18.432 | J11: =I11*30 -> 552.96
B13: Instancia Basica Ubuntu | F13: R$ p/ Mês | H13: Disco Gb | I13: Disco R$ /Mês | N13: R$ Total / Mês
B14: 1Gb | C14: RAM | D14: 1 | E14: Core | F14: =J8 -> 115.2 | H14: 60 | I14: =H14*N2 -> 43.8 | N14: =I14+F14 -> 159
B15: Escala Até
B16: 4GB | C16: RAM | D16: 4 | E16: Core | F16: =J10 -> 276.48 | H16: 100 | I16: =H16*N2 -> 73 | N16: =I16+F16 -> 349.48
B19: Instancia basica Windows | F19: R$ p/ Mês | H19: Disco Gb | I19: Disco R$ /Mês | K19: IP Publico | N19: R$ Total / Mês | P19: Total W + L | Q19: user
B20: 4Gb | C20: RAM | D20: 2 | E20: Core | F20: =J10 -> 276.48 | H20: 30 | I20: =H20*N2 -> 21.9 | K20: =T2 -> 20.44 | N20: =I20+F20+K20 -> 318.82 | P20: =N20+N14 -> 477.82 | Q20: 6
B21: Escala Até
B22: 8Gb | C22: RAM | D22: 2 | E22: Core | F22: =J11 -> 552.96 | H22: 30 | I22: =H22*N2 -> 21.9 | K22: =T2 -> 20.44 | N22: =I22+F22+K22 -> 595.3 | P22: =N22+N16 -> 944.78 | Q22: 10
B24: Licenças TS Por Usuario | E24: Mhz | F24: RAM Mb
B25: 32 | E25: 400 | F25: 128
B27: FTP STORAGE = R$35,80 por Mês. | F27: 35.8
B29: Recomendações Microsoft para Usuarios TS no Windows server 64 Mb RAM.
B31: Recomendações SaveIncloud por Usuario para acesso TS
B32: 400Mhz e 128Mb RAM
B34: Processo teste utilizado e funcionou sem travamento e com fluidez desejavel.
B35: Estação Windows Basica 4Gb RAM e 1CPU
B36: 4Gb Extra de RAM (2Gb para 10 usuarios e 2 Gb extra para processamentos)
B37: 1 Maquina 8Gb RAM e 1 VCP = R$395,00

Sheet PM BI
A1: EMPRESA | B1: PRODUTO | C1: VALOR | D1: QTDE | E1: ADITIVO&CONTRATO
A2: PAROLAR | B2: BI | C2: 1563.89 | D2: 1 | E2: 44354
A3: SCOTTI | B3: BI | C3: 974.2 | D3: 1 | E3: 44381
A4: ATIVA | B4: BI | C4: 1271.15 | D4: 1 | E4: 44648
A5: MOLIN | B5: BI | C5: 1400 | D5: 1 | E5: 45020
A6: CLASSHOME | B6: BI | C6: 1400 | D6: 1 | E6: 45140
A7: ARGIVAÍ | B7: BI | C7: 900 | D7: 1 | E7: 45257
A8: RUVOLO | B8: BI | C8: 1600 | D8: 1 | E8: 45365
A9: MUNDI | B9: BI | C9: 972 | D9: 1 | E9: 45377
C10: QTDE | D10: =SUM(D2:D9) -> 8
C11: PM | D11: =(C2*D2+C3*D3+C4*D4+C5*D5+C6*D6+C7*D7+C8*D8+C9*D9)/D10 -> 1260.155
C12: PM | D12: =MEDIAN(C8:C9) -> 1286

Sheet ||
