Workbook

Sheet Pendentes
A1: Data | B1: Ticket | C1: Vendedor | D1: Cliente | E1: Produto | F1: TipoReceita | G1: Qtde | H1: VlrUnitário | I1: VlrTotal | J1: Vlr Meta | K1: %Comissão | L1: %ComissãoSupervisor | M1: Base | N1: ComissãoVendedor | O1: ComissãoSupervisor | P1: Clicksign | Q1: Contrato_Termo Aditivo | R1: Obs | S1: Parcelas | T1: Data Contrato | U1: Contrato | V1: SDR_RESPONSÁVEL
A2: 46147 | B2: 141516 | C2: Rayssa Karapeticov | D2: Zein | E2: loja B2B | F2: Mensalidade | G2: 1 | H2: 3001.35 | I2: =vendas2026[[#This Row],[Qtde]]*vendas2026[[#This Row],[VlrUnitário]] -> 21060 | J2: =(vendas2026[[#This Row],[VlrTotal]]*0.2)+vendas2026[[#This Row],[VlrTotal]] -> 21404.52 | K2: 1 | L2: =vendas2026[[#This Row],[%Comissão]]*0.25 -> 0.0175 | M2: Sim | N2: =vendas2026[[#This Row],[VlrTotal]]*vendas2026[[#This Row],[%Comissão]] -> 1248.597 | O2: =vendas2026[[#This Row],[VlrTotal]]*vendas2026[[#This Row],[%ComissãoSupervisor]] -> 0 | P2: Feito | Q2: Feito | S2: 1 | T2: 46156 | U2: Pendente | V2: Rayssa Karapeticov
A3: 46154 | B3: 142403 | C3: Rayssa Karapeticov | D3: Maquimp | E3: ERP | F3: Treinamentos e Implantações | G3: 280 | H3: 210 | I3: =vendas2026[[#This Row],[Qtde]]*vendas2026[[#This Row],[VlrUnitário]] -> 840 | J3: =vendas2026[[#This Row],[VlrTotal]] -> 840 | K3: 0.07 | L3: =vendas2026[[#This Row],[%Comissão]]*0.25 -> 0.25 | M3: Não | N3: =vendas2026[[#This Row],[VlrTotal]]*vendas2026[[#This Row],[%Comissão]] -> 840 | O3: =vendas2026[[#This Row],[VlrTotal]]*vendas2026[[#This Row],[%ComissãoSupervisor]] -> 0 | P3: Feito | Q3: Feito | S3: 10 | U3: Pendente | V3: Rayssa Karapeticov
A4: 46154 | B4: 142403 | C4: Rayssa Karapeticov | D4: Maquimp | E4: ERP | F4: Mensalidade | G4: 14 | H4: 275.82 | I4: =vendas2026[[#This Row],[Qtde]]*vendas2026[[#This Row],[VlrUnitário]] -> 7999.8 | J4: =vendas2026[[#This Row],[VlrTotal]] -> 7999.8 | K4: 1 | L4: =vendas2026[[#This Row],[%Comissão]]*0.25 -> 0.016675 | M4: Não | N4: =vendas2026[[#This Row],[VlrTotal]]*vendas2026[[#This Row],[%Comissão]] -> 533.58666 | O4: =vendas2026[[#This Row],[VlrTotal]]*vendas2026[[#This Row],[%ComissãoSupervisor]] -> 133.39667 | P4: Feito | Q4: Feito | S4: 1 | U4: Pendente | V4: Rayssa Karapeticov
A5: 46154 | B5: 142403 | C5: Rayssa Karapeticov | D5: Maquimp | E5: Telemarketing | F5: Mensalidade | G5: 1 | H5: 320.76 | I5: =vendas2026[[#This Row],[Qtde]]*vendas2026[[#This Row],[VlrUnitário]] -> 986.7 | J5: =vendas2026[[#This Row],[VlrTotal]] -> 986.7 | K5: 1 | L5: =vendas2026[[#This Row],[%Comissão]]*0.25 -> 0.25 | M5: Não | N5: =vendas2026[[#This Row],[VlrTotal]]*vendas2026[[#This Row],[%Comissão]] -> 986.7 | O5: =vendas2026[[#This Row],[VlrTotal]]*vendas2026[[#This Row],[%ComissãoSupervisor]] -> 246.675 | P5: Feito | Q5: Feito | S5: 1 | U5: Pendente | V5: Rayssa Karapeticov

Sheet 2026
A1: Data | B1: Ticket | C1: Vendedor | D1: Cliente | E1: Produto | F1: TipoReceita | G1: Qtde | H1: VlrUnitário | I1: VlrTotal | J1: Vlr Meta | K1: %Comissão | L1: %ComissãoSupervisor | M1: Base | N1: ComissãoVendedor | O1: ComissãoSupervisor | P1: Clicksign | Q1: Contrato_Termo Aditivo | R1: Obs | S1: Parcelas | T1: Data Contrato | U1: Contrato | V1: SDR_RESPONSÁVEL
A2: 46027 | B2: 133837 | C2: Paulo Souza | D2: PlastCap | E2: Treinamento | F2: Treinamentos e Implantações | G2: 180 | H2: 117 | I2: 17837.1 | K2: 0.07 | L2: 0 | M2: Sim | N2: 1248.597 | O2: 0 | P2: Feito | Q2: Feito | S2: 12 | U2: Assinado | V2: Paulo Souza
A3: 46027 | B3: 133837 | C3: Paulo Souza | D3: PlastCap | E3: ERP-PDV | F3: Mensalidade | G3: 3 | H3: 280 | I3: 840 | K3: 1 | L3: 0 | M3: Sim | N3: 840 | O3: 0 | P3: Feito | Q3: Feito | S3: 1 | U3: Assinado | V3: Paulo Souza
A4: 46027 | B4: 135649 | C4: Rayssa Karapeticov | D4: MB Plasticos | E4: Treinamento | F4: Treinamentos e Implantações | G4: 60 | H4: 133.33 | I4: =vendas2026[[#This Row],[Qtde]]*vendas2026[[#This Row],[VlrUnitário]] -> 7999.8 | K4: 0.0667 | L4: =vendas2026[[#This Row],[%Comissão]]*0.25 -> 0.016675 | M4: Sim | N4: =vendas2026[[#This Row],[VlrTotal]]*vendas2026[[#This Row],[%Comissão]] -> 533.58666 | O4: =vendas2026[[#This Row],[VlrTotal]]*vendas2026[[#This Row],[%ComissãoSupervisor]] -> 133.39667 | P4: Feito | Q4: Feito | S4: 3 | U4: Assinado | V4: Rayssa Karapeticov
A5: 46027 | B5: 135649 | C5: Rayssa Karapeticov | D5: MB Plasticos | E5: AFV Proposta WEB | F5: Mensalidade | G5: 78 | H5: 12.65 | I5: =vendas2026[[#This Row],[VlrUnitário]]*vendas2026[[#This Row],[Qtde]] -> 986.7 | K5: 1 | L5: =vendas2026[[#This Row],[%Comissão]]*0.25 -> 0.25 | M5: Sim | N5: =vendas2026[[#This Row],[VlrTotal]]*vendas2026[[#This Row],[%Comissão]] -> 986.7 | O5: =vendas2026[[#This Row],[VlrTotal]]*vendas2026[[#This Row],[%ComissãoSupervisor]] -> 246.675 | P5: Feito | Q5: Feito | S5: 1 | U5: Assinado | V5: Rayssa Karapeticov
A6: 46034 | B6: 134739 | C6: Rayssa Karapeticov | D6: Dolce Home | E6: Melhoria | F6: Melhoria | G6: 6 | H6: 158.401 | I6: =vendas2026[[#This Row],[VlrUnitário]]*vendas2026[[#This Row],[Qtde]] -> 950.406 | K6: 0.007 | L6: =vendas2026[[#This Row],[%Comissão]]*0.25 -> 0.00175 | M6: Sim | N6: =vendas2026[[#This Row],[VlrTotal]]*vendas2026[[#This Row],[%Comissão]] -> 6.652842 | O6: =vendas2026[[#This Row],[VlrTotal]]*vendas2026[[#This Row],[%ComissãoSupervisor]] -> 1.6632105 | P6: Não tem | Q6: não tem | S6: 1 | U6: não tem | V6: Rayssa Karapeticov
A7: 46034 | B7: 136315 | C7: Paulo Souza | D7: Akitem | E7: CNPJ | F7: CDU | G7: 1 | H7: 15053.87 | I7: =vendas2026[[#This Row],[VlrUnitário]]*vendas2026[[#This Row],[Qtde]] -> 15053.87 | K7: 0.07 | L7: 0 | M7: Sim | N7: =vendas2026[[#This Row],[VlrTotal]]*vendas2026[[#This Row],[%Comissão]] -> 1053.7709 | O7: =vendas2026[[#This Row],[VlrTotal]]*vendas2026[[#This Row],[%ComissãoSupervisor]] -> 0 | P7: Feito | Q7: Feito | S7: 6 | U7: Assinado | V7: Paulo Souza
A8: 46034 | B8: 136315 | C8: Paulo Souza | D8: Akitem | E8: ERP | F8: Mensalidade | G8: 1 | H8: 275.62 | I8: =vendas2026[[#This Row],[VlrUnitário]]*vendas2026[[#This Row],[Qtde]] -> 275.62 | K8: 1 | L8: 0 | M8: Sim | N8: =vendas2026[[#This Row],[VlrTotal]]*vendas2026[[#This Row],[%Comissão]] -> 275.62 | O8: =vendas2026[[#This Row],[VlrTotal]]*vendas2026[[#This Row],[%ComissãoSupervisor]] -> 0 | P8: Feito | Q8: Feito | S8: 1 | U8: Assinado | V8: Paulo Souza
A9: 46043 | B9: 132374 | C9: Rayssa Karapeticov | D9: Keita | E9: Treinamento | F9: Treinamentos e Implantações | G9: 94 | H9: 178.5 | I9: =vendas2026[[#This Row],[VlrUnitário]]*vendas2026[[#This Row],[Qtde]] -> 16779 | K9: 0.0667 | L9: =vendas2026[[#This Row],[%Comissão]]*0.25 -> 0.016675 | M9: Sim | N9: =vendas2026[[#This Row],[VlrTotal]]*vendas2026[[#This Row],[%Comissão]] -> 1119.1593 | O9: =vendas2026[[#This Row],[VlrTotal]]*vendas2026[[#This Row],[%ComissãoSupervisor]] -> 279.78983 | P9: Não tem | Q9: não tem | S9: 10 | U9: Assinado | V9: Rayssa Karapeticov
A10: 46043 | B10: 132678 | C10: Junior Lopes | D10: Amilplast | E10: Treinamento | F10: Treinamentos e Implantações | G10: 270 | H10: 190 | I10: =G10*H10 -> 51300 | K10: 0.07 | L10: =K10*0.25 -> 0.0175 | M10: Não | N10: =(K10*I10) -> 3591 | O10: =I10*L10 -> 897.75 | P10: Feito | Q10: Feito | S10: 10 | U10: Assinado | V10: Junior Lopes
A11: 46043 | B11: 132678 | C11: Junior Lopes | D11: Amilplast | E11: ERP | F11: Mensalidade | G11: 5 | H11: 275.62 | I11: =G11*H11 -> 1378.1 | K11: 1 | L11: =K11*0.25 -> 0.25 | M11: Não | N11: =(K11*I11) -> 1378.1 | O11: =I11*L11 -> 344.525 | P11: Feito | Q11: Feito | S11: 1 | U11: Assinado | V11: Junior Lopes
A12: 46043 | B12: 132678 | C12: Junior Lopes | D12: Amilplast | E12: MDE | F12: Mensalidade | G12: 1 | H12: 356.4 | I12: =G12*H12 -> 356.4 | K12: 1 | L12: =K12*0.25 -> 0.25 | M12: Não | N12: =(K12*I12) -> 356.4 | O12: =I12*L12 -> 89.1 | P12: Feito | Q12: Feito | S12: 1 | U12: Assinado | V12: Junior Lopes
A13: 46043 | B13: 136662 | C13: Rayssa Karapeticov | D13: Nixhouse | E13: Treinamento | F13: Treinamentos e Implantações | G13: 10 | H13: 210 | I13: =G13*H13 -> 2100 | K13: 0.07 | L13: =K13*0.25 -> 0.0175 | M13: Sim | N13: =(K13*I13) -> 147 | O13: =I13*L13 -> 36.75 | P13: Não tem | Q13: não tem | S13: 4 | U13: não tem | V13: Rayssa Karapeticov
A14: 46043 | B14: 136717,136720,136721 | C14: Paulo Souza | D14: NVT Importadora | E14: ERP | F14: Treinamentos e Implantações | G14: 240 | H14: 200 | I14: =G14*H14 -> 48000 | K14: 0.07 | L14: 0 | M14: Não | N14: =(K14*I14) -> 3360 | O14: =I14*L14 -> 0 | P14: Feito | Q14: Feito | S14: 6 | U14: Assinado | V14: Paulo Souza
A15: 46043 | B15: 136717,136720,136721 | C15: Paulo Souza | D15: NVT Importadora | E15: BI | F15: CDU | G15: 1 | H15: 8100 | I15: =G15*H15 -> 8100 | K15: 0.07 | L15: 0 | M15: Não | N15: =(K15*I15) -> 567 | O15: =I15*L15 -> 0 | P15: Feito | Q15: Feito | S15: 6 | U15: Assinado | V15: Paulo Souza
A16: 46043 | B16: 136717,136720,136721 | C16: Paulo Souza | D16: NVT Importadora | E16: CLOUD | F16: CDU | G16: 1 | H16: 1600 | I16: =G16*H16 -> 1600 | K16: 0.07 | L16: 0 | M16: Não | N16: =(K16*I16) -> 112 | O16: =I16*L16 -> 0 | P16: Feito | Q16: Feito | S16: 6 | U16: Assinado | V16: Paulo Souza
A17: 46043 | B17: 136717,136720,136721 | C17: Paulo Souza | D17: NVT Importadora | E17: ERP | F17: Mensalidade | G17: 8 | H17: 250 | I17: =G17*H17 -> 2000 | K17: 1 | L17: 0 | M17: Não | N17: =(K17*I17) -> 2000 | O17: =I17*L17 -> 0 | P17: Feito | Q17: Feito | S17: 1 | U17: Assinado | V17: Paulo Souza
A18: 46043 | B18: 136717,136720,136721 | C18: Paulo Souza | D18: NVT Importadora | E18: WMS | F18: Mensalidade | G18: 4 | H18: 100 | I18: =G18*H18 -> 400 | K18: 1 | L18: 0 | M18: Não | N18: =(K18*I18) -> 400 | O18: =I18*L18 -> 0 | P18: Feito | Q18: Feito | S18: 1 | U18: Assinado | V18: Paulo Souza
A19: 46043 | B19: 136717,136720,136721 | C19: Paulo Souza | D19: NVT Importadora | E19: BI | F19: Mensalidade | G19: 1 | H19: 1080 | I19: =G19*H19 -> 1080 | K19: 1 | L19: 0 | M19: Não | N19: =(K19*I19) -> 1080 | O19: =I19*L19 -> 0 | P19: Feito | Q19: Feito | S19: 1 | U19: Assinado | V19: Paulo Souza
A20: 46043 | B20: 136717,136720,136721 | C20: Paulo Souza | D20: NVT Importadora | E20: AFV | F20: Mensalidade | G20: 30 | H20: 90 | I20: =G20*H20 -> 2700 | K20: 1 | L20: 0 | M20: Não | N20: =(K20*I20) -> 2700 | O20: =I20*L20 -> 0 | P20: Feito | Q20: Feito | S20: 1 | U20: Assinado | V20: Paulo Souza
A21: 46043 | B21: 136717,136720,136721 | C21: Paulo Souza | D21: NVT Importadora | E21: MDE | F21: Mensalidade | G21: 1 | H21: 356.4 | I21: =G21*H21 -> 356.4 | K21: 1 | L21: 0 | M21: Não | N21: =(K21*I21) -> 356.4 | O21: =I21*L21 -> 0 | P21: Feito | Q21: Feito | S21: 1 | U21: Assinado | V21: Paulo Souza
A22: 46043 | B22: 136717,136720,136721 | C22: Paulo Souza | D22: NVT Importadora | E22: Envio Boleto Whatsapp | F22: Mensalidade | G22: 1 | H22: 197 | I22: =G22*H22 -> 197 | K22: 1 | L22: 0 | M22: Não | N22: =(K22*I22) -> 197 | O22: =I22*L22 -> 0 | P22: Feito | Q22: Feito | S22: 1 | U22: Assinado | V22: Paulo Souza
A23: 46043 | B23: 136717,136720,136721 | C23: Paulo Souza | D23: NVT Importadora | E23: CLOUD | F23: Mensalidade | G23: 1 | H23: 2524.72 | I23: =G23*H23 -> 2524.72 | K23: 1 | L23: 0 | M23: Não | N23: =(K23*I23) -> 2524.72 | O23: =I23*L23 -> 0 | P23: Feito | Q23: Feito | S23: 1 | U23: Assinado | V23: Paulo Souza
A24: 46043 | B24: 114426 | C24: Rayssa Karapeticov | D24: Culturama | E24: Treinamento | F24: Treinamentos e Implantações | G24: 11 | H24: 210 | I24: =G24*H24 -> 2310 | K24: 0.07 | L24: =K24*0.25 -> 0.0175 | M24: Sim | N24: =(K24*I24) -> 161.7 | O24: =I24*L24 -> 40.425 | P24: Não tem | Q24: não tem | S24: 6 | U24: não tem | V24: Rayssa Karapeticov
A25: 46043 | B25: 136856 | C25: Rayssa Karapeticov | D25: Rischiotto | E25: Adicional Intelipost | F25: Treinamentos e Implantações | G25: 16 | H25: 178.5 | I25: =G25*H25 -> 2856 | K25: 0.0667 | L25: =K25*0.25 -> 0.016675 | M25: Sim | N25: =(K25*I25) -> 190.4952 | O25: =I25*L25 -> 47.6238 | P25: Feito | Q25: Feito | S25: 6 | U25: Assinado | V25: Rayssa Karapeticov
A26: 46043 | B26: 136856 | C26: Rayssa Karapeticov | D26: Rischiotto | E26: Adicional Intelipost | F26: Mensalidade | G26: 1 | H26: 641.52 | I26: =G26*H26 -> 641.52 | K26: 1 | L26: =K26*0.25 -> 0.25 | M26: Sim | N26: =(K26*I26) -> 641.52 | O26: =I26*L26 -> 160.38 | P26: Feito | Q26: Feito | S26: 1 | U26: Assinado | V26: Rayssa Karapeticov
A27: 46044 | B27: 134776 | C27: Rayssa Karapeticov | D27: Qualyplast | E27: Melhoria | F27: Melhoria | G27: 8 | H27: 176 | I27: =G27*H27 -> 1408 | K27: 0.01 | L27: =K27*0.25 -> 0.0025 | M27: Sim | N27: =(K27*I27) -> 14.08 | O27: =I27*L27 -> 3.52 | P27: Não tem | Q27: não tem | S27: 3 | U27: não tem | V27: Rayssa Karapeticov
A28: 46044 | B28: 136981 | C28: Rayssa Karapeticov | D28: Dolce Home | E28: CNPJ | F28: CDU | G28: 1 | H28: 2419.18 | I28: =G28*H28 -> 2419.18 | K28: 0.06667 | L28: =K28*0.25 -> 0.0166675 | M28: Sim | N28: =(K28*I28) -> 161.28673 | O28: =I28*L28 -> 40.321683 | P28: Feito | Q28: Feito | S28: 6 | U28: Assinado | V28: Rayssa Karapeticov
A29: 46044 | B29: 136981 | C29: Rayssa Karapeticov | D29: Dolce Home | E29: CNPJ | F29: Treinamentos e Implantações | G29: 16 | H29: 178.68 | I29: =G29*H29 -> 2858.88 | K29: 0.0667 | L29: =K29*0.25 -> 0.016675 | M29: Sim | N29: =(K29*I29) -> 190.6873 | O29: =I29*L29 -> 47.671824 | P29: Feito | Q29: Feito | S29: 6 | U29: Assinado | V29: Rayssa Karapeticov
A30: 46048 | B30: 137055 | C30: Rayssa Karapeticov | D30: GP Inox | E30: BI | F30: CDU | G30: 1 | H30: 8100 | I30: =G30*H30 -> 8100 | K30: 0.07 | L30: =K30*0.25 -> 0.0175 | M30: Sim | N30: =(K30*I30) -> 567 | O30: =I30*L30 -> 141.75 | P30: Feito | Q30: Feito | S30: 6 | U30: Assinado | V30: Rayssa Karapeticov
A31: 46048 | B31: 137055 | C31: Rayssa Karapeticov | D31: GP Inox | E31: BI | F31: Mensalidade | G31: 1 | H31: 1070 | I31: =G31*H31 -> 1070 | K31: 1 | L31: =K31*0.25 -> 0.25 | M31: Sim | N31: =(K31*I31) -> 1070 | O31: =I31*L31 -> 267.5 | P31: Feito | Q31: Feito | S31: 1 | U31: Assinado | V31: Rayssa Karapeticov
A32: 46052 | B32: 137171 | C32: Junior Lopes | D32: RN Porcelanas | E32: ERP | F32: Treinamentos e Implantações | G32: 300 | H32: 166.67 | I32: =G32*H32 -> 50001 | K32: 0.05 | L32: =K32*0.25 -> 0.0125 | M32: Não | N32: =(K32*I32) -> 2500.05 | O32: =I32*L32 -> 625.0125 | P32: Feito | Q32: Feito | S32: 10 | U32: Assinado | V32: Junior Lopes
A33: 46052 | B33: 137171 | C33: Junior Lopes | D33: RN Porcelanas | E33: ERP | F33: Mensalidade | G33: 7 | H33: 240 | I33: =G33*H33 -> 1680 | K33: 1 | L33: =K33*0.25 -> 0.25 | M33: Não | N33: =(K33*I33) -> 1680 | O33: =I33*L33 -> 420 | P33: Feito | Q33: Feito | S33: 1 | U33: Assinado | V33: Junior Lopes
A34: 46052 | B34: 137171 | C34: Junior Lopes | D34: RN Porcelanas | E34: WMS | F34: Mensalidade | G34: 1 | H34: 140 | I34: =G34*H34 -> 140 | K34: 1 | L34: =K34*0.25 -> 0.25 | M34: Não | N34: =(K34*I34) -> 140 | O34: =I34*L34 -> 35 | P34: Feito | Q34: Feito | S34: 1 | U34: Assinado | V34: Junior Lopes
A35: 46052 | B35: 137171 | C35: Junior Lopes | D35: RN Porcelanas | E35: AFV | F35: Mensalidade | G35: 10 | H35: 88 | I35: =G35*H35 -> 880 | K35: 1 | L35: =K35*0.25 -> 0.25 | M35: Não | N35: =(K35*I35) -> 880 | O35: =I35*L35 -> 220 | P35: Feito | Q35: Feito | S35: 1 | U35: Assinado | V35: Junior Lopes
... A38: 46052 | B38: 137309 | C38: Rayssa Karapeticov | D38: ArcaPlast | E38: Melhoria | F38: Melhoria | G38: 5 | H38: 176 | I38: =G38*H38 -> 880 | K38: 0.01 | L38: =K38*0.25 -> 0.0025 | M38: Sim | N38: =(K38*I38) -> 8.8 | O38: =I38*L38 -> 2.2 | P38: Não tem | Q38: não tem | S38: 3 | U38: não tem | V38: Rayssa Karapeticov
A39: 46052 | B39: 125596 | C39: Paulo Souza | D39: Agua Sana | E39: Treinamento | F39: Treinamentos e Implantações | G39: 40 | H39: 180 | I39: =G39*H39 -> 7200 | K39: 0.07 | L39: 0 | M39: Sim | N39: =(K39*I39) -> 504 | O39: =I39*L39 -> 0 | P39: Não tem | Q39: não tem | S39: 6 | U39: não tem | V39: Paulo Souza
A40: 46055 | B40: 130904 | C40: Junior Lopes | D40: Tiago eletronicos | E40: B2B | F40: CDU | G40: 1 | H40: 22270 | I40: =vendas2026[[#This Row],[VlrUnitário]]*vendas2026[[#This Row],[Qtde]] -> 22270 | J40: =vendas2026[[#This Row],[VlrTotal]] -> 22270 | K40: 0.07 | L40: =vendas2026[[#This Row],[%Comissão]]*0.25 -> 0.0175 | M40: Não | N40: =vendas2026[[#This Row],[VlrTotal]]*vendas2026[[#This Row],[%Comissão]] -> 1558.9 | O40: =vendas2026[[#This Row],[VlrTotal]]*vendas2026[[#This Row],[%ComissãoSupervisor]] -> 389.725 | P40: Feito | Q40: Feito | S40: 10 | U40: Assinado | V40: Junior Lopes
A41: 46055 | B41: 130904 | C41: Junior Lopes | D41: Tiago eletronicos | E41: B2B | F41: Mensalidade | G41: 1 | H41: 3000 | I41: =vendas2026[[#This Row],[VlrUnitário]]*vendas2026[[#This Row],[Qtde]] -> 3000 | J41: =(vendas2026[[#This Row],[VlrTotal]]*0.2)+vendas2026[[#This Row],[VlrTotal]] -> 3600 | K41: 1 | L41: =vendas2026[[#This Row],[%Comissão]]*0.25 -> 0.25 | M41: Não | N41: =vendas2026[[#This Row],[VlrTotal]]*vendas2026[[#This Row],[%Comissão]] -> 3000 | O41: =vendas2026[[#This Row],[VlrTotal]]*vendas2026[[#This Row],[%ComissãoSupervisor]] -> 750 | P41: Feito | Q41: Feito | S41: 1 | U41: Assinado | V41: Junior Lopes
A42: 46055 | B42: 128860 | C42: Paulo Souza | D42: Sagol | E42: Treinamento | F42: Treinamentos e Implantações | G42: 110 | H42: 185 | I42: =vendas2026[[#This Row],[Qtde]]*vendas2026[[#This Row],[VlrUnitário]] -> 20350 | J42: 20350 | K42: 0.07 | L42: 0 | M42: Não | N42: =vendas2026[[#This Row],[VlrTotal]]*vendas2026[[#This Row],[%Comissão]] -> 1424.5 | O42: 0 | P42: Não tem | Q42: não tem | S42: 6 | U42: não tem | V42: Paulo Souza
...

Sheet Metas Quadro
A1: TABELA 1.1
A3: Juca | B3: Meta | C3: Alvo | D3: Cobertura
A4: Projeto | B4: 90000 | C4: 86455.76 | D4: =C4/B4 -> 0.96061956
A5: Recorrente | B5: 10000 | C5: 448 | D5: =C5/B5 -> 0.0448
A7: Rayssa
A8: Projeto | B8: 90000 | C8: 16300 | D8: =C8/B8 -> 0.18111111
A9: Recorrente | B9: 9500 | C9: 10463.76 | D9: =C9/B9 -> 1.1014484
A12: Paulo | B12: Meta | C12: Alvo | D12: Cobertura
A13: Projeto | B13: 90000 | C13: 0 | D13: =C13/B13 -> 0
A14: Recorrente | B14: 10000 | C14: 0 | D14: =C14/B14 -> 0
A16: Ronaldo Nascimento | B16: Meta | C16: Alvo | D16: Cobertura
A17: Projeto | B17: 54000 | C17: 0 | D17: =C17/B17 -> 0
A18: Recorrente | B18: 7500 | C18: 0 | D18: =C18/B18 -> 0
A20: Fábio | B20: Meta | C20: Alvo | D20: Cobertura
A21: Projeto | B21: 90000 | C21: 0 | D21: =C21/B21 -> 0
A22: Recorrente | B22: 10000 | C22: 0 | D22: =C22/B22 -> 0
A24: Total Projeto Equipe | B24: =90000*4 -> 360000 | C24: =C4+C8+C13+C21+C17 -> 102755.76 | D24: =C24/B24 -> 0.28543267
A25: Total RecorrenteEquipe | B25: =B9+B14+B18+B5 -> 37000 | C25: =C5+C9+C14+C18 -> 10911.76 | D25: =C25/B25 -> 0.29491243
A27: Meta Equipe | B27: Meta | C27: Alvo | D27: Cobertura
A28: Projeto | B28: =90000*4 -> 360000 | C28: =C4+C8+C13+C17 -> 102755.76 | D28: =C28/B28 -> 0.28543267
A29: Recorrente | B29: =B25 -> 37000 | C29: =C9+C14+C18+C5 -> 10911.76 | D29: =C29/B29 -> 0.29491243

Sheet QtdeMetas
A1: FECHAMENTO DE: 01/01/2025 até 31/01/2025 | M1: Ano | N1: Mês | O1: Vendedor | P1: Lead | Q1: Propsota | R1: Apresentação | S1: Meta Individual | T1: Meta Equipe | U1: Meta Projetos | V1: OBLead | W1: OB Proposta | X1: OB Apresentação | Y1: OB Individual | Z1: OBEquipe | AA1: OB Projetos | AB1: OBI | AC1: OBE
A2: COBERTURA DE METAS | M2: 2025 | N2: 45658 | O2: Rayssa Karapeticov | Q2: =C5 -> 33 | R2: =C6 -> 18 | S2: =C7 -> 926.64 | T2: =C8 -> 32622.62 | U2: =C9 -> 62289.8 | V2: 150 | W2: 15 | X2: 12 | Y2: 10 | Z2: 30 | AA2: 90000 | AB2: =metas[[#This Row],[Meta Individual]]/10000 -> 0.092664 | AC2: =metas[[#This Row],[Meta Equipe]]/30000/3 -> 0.36247356
A3: RAYSSA | E3: JUNIOR | I3: PAULO | M3: 2025 | N3: 45658 | O3: Junior Lopes | Q3: =G5 -> 14 | R3: =G6 -> 12 | S3: =G7 -> 31339.58 | T3: =G8 -> 32622.62 | U3: =G9 -> 315102.82 | V3: 150 | W3: 15 | X3: 12 | Y3: 10 | Z3: 30 | AA3: 90000 | AB3: =metas[[#This Row],[Meta Individual]]/10000 -> 3.133958 | AC3: =metas[[#This Row],[Meta Equipe]]/30000/3 -> 0.36247356
B4: Meta | C4: Realizado | D4: Cobertura | F4: Meta | G4: Realizado | H4: Cobertura | J4: Meta | K4: Realizado | L4: Cobertura | M4: 2025 | N4: 45658 | O4: Paulo Souza | Q4: =K5 -> 15 | R4: =K6 -> 16 | S4: =K7 -> 356.4 | T4: =K8 -> 32622.62 | U4: =K9 -> 14022.08 | V4: 150 | W4: 15 | X4: 12 | Y4: 10 | Z4: 30 | AA4: 90000 | AB4: =metas[[#This Row],[Meta Individual]]/10000 -> 0.03564 | AC4: =metas[[#This Row],[Meta Equipe]]/30000/3 -> 0.36247356
A5: Proposta | B5: 15 | C5: 33 | D5: 2.2 | E5: Proposta | F5: 15 | G5: 14 | H5: 0.93333333 | I5: Proposta | J5: 15 | K5: 15 | L5: 1 | M5: 2025 | N5: 45689 | O5: Rayssa Karapeticov | Q5: =C15 -> 23 | R5: =C16 -> 22 | S5: =C17 -> 1288.03 | T5: =C18 -> 14565.4 | U5: =C19 -> 85015.22 | V5: 150 | W5: 15 | X5: 12 | Y5: 10 | Z5: 30 | AA5: 90000 | AB5: =metas[[#This Row],[Meta Individual]]/10000 -> 0.128803 | AC5: =metas[[#This Row],[Meta Equipe]]/30000/3 -> 0.16183778
A6: Apresentações | B6: 12 | C6: 18 | D6: 1.5 | E6: Apresentações | F6: 12 | G6: 12 | H6: 1 | I6: Apresentações | J6: 12 | K6: 16 | L6: 1.3333333 | M6: 2025 | N6: 45689 | O6: Junior Lopes | Q6: =G15 -> 16 | R6: =G16 -> 16 | S6: =G17 -> 11189.93 | T6: =G18 -> 14565.4 | U6: =G19 -> 121887.86 | V6: 150 | W6: 15 | X6: 12 | Y6: 10 | Z6: 30 | AA6: 90000 | AB6: =metas[[#This Row],[Meta Individual]]/10000 -> 1.118993 | AC6: =metas[[#This Row],[Meta Equipe]]/30000/3 -> 0.16183778
A7: Meta Individual | B7: 10000 | C7: 926.64 | D7: 0.092664 | E7: Meta Individual | F7: 10000 | G7: 31339.58 | H7: 3.133958 | I7: Meta Individual | J7: 10000 | K7: 356.4 | L7: 0.03564 | M7: 2025 | N7: 45689 | O7: Paulo Souza | Q7: =K15 -> 9 | R7: =K16 -> 21 | S7: =K17 -> 2087.44 | T7: =K18 -> 14565.4 | U7: =K19 -> 19104 | V7: 150 | W7: 15 | X7: 12 | Y7: 10 | Z7: 30 | AA7: 90000 | AB7: =metas[[#This Row],[Meta Individual]]/10000 -> 0.208744 | AC7: =metas[[#This Row],[Meta Equipe]]/30000/3 -> 0.16183778
A8: Meta Equipe | B8: 30000 | C8: 32622.62 | D8: 1.0874207 | E8: Meta Equipe | F8: 30000 | G8: 32622.62 | H8: 1.0874207 | I8: Meta Equipe | J8: 30000 | K8: 32622.62 | L8: 1.0874207 | M8: 2025 | N8: 45717 | O8: Rayssa Karapeticov | Q8: =C25 -> 17 | R8: =C26 -> 7 | S8: =C27 -> 6712.41 | T8: =C28 -> 14901.7 | U8: =C29 -> 111207.36 | V8: 150 | W8: 15 | X8: 12 | Y8: 10 | Z8: 30 | AA8: 90000 | AB8: =metas[[#This Row],[Meta Individual]]/10000 -> 0.671241 | AC8: =metas[[#This Row],[Meta Equipe]]/30000/3 -> 0.16557444
A9: Meta Projetos | B9: 90000 | C9: 62289.8 | D9: 0.69210889 | E9: Meta Projetos | F9: 90000 | G9: 315102.82 | H9: 3.5011424 | I9: Meta Projetos | J9: 90000 | K9: 14022.08 | L9: 0.15580089 | M9: 2025 | N9: 45717 | O9: Junior Lopes | Q9: =G25 -> 17 | R9: =G26 -> 12 | S9: =G27 -> 3064.57 | T9: =G28 -> 14901.7 | U9: =G29 -> 70833.33 | V9: 150 | W9: 15 | X9: 12 | Y9: 10 | Z9: 30 | AA9: 90000 | AB9: =metas[[#This Row],[Meta Individual]]/10000 -> 0.306457 | AC9: =metas[[#This Row],[Meta Equipe]]/30000/3 -> 0.16557444
M10: 2025 | N10: 45717 | O10: Paulo Souza | Q10: =K25 -> 4 | R10: =K26 -> 4 | S10: =K27 -> 5124.72 | T10: =K28 -> 14901.7 | U10: =K29 -> 73632 | V10: 150 | W10: 15 | X10: 12 | Y10: 10 | Z10: 30 | AA10: 90000 | AB10: =metas[[#This Row],[Meta Individual]]/10000 -> 0.512472 | AC10: =metas[[#This Row],[Meta Equipe]]/30000/3 -> 0.16557444
A11: FECHAMENTO DE: 01/02/2025 até 28/02/2025 | M11: 2025 | N11: 45748 | O11: Rayssa Karapeticov | Q11: =C35 -> 29 | R11: =C36 -> 15 | S11: =C37 -> 193 | T11: =C38 -> 13345.68 | U11: =C39 -> 29258.82 | V11: 150 | W11: 15 | X11: 12 | Y11: 10 | Z11: 30 | AA11: 90000 | AB11: =metas[[#This Row],[Meta Individual]]/10000 -> 0.0193 | AC11: =metas[[#This Row],[Meta Equipe]]/30000/3 -> 0.14828533
A12: COBERTURA DE METAS | M12: 2025 | N12: 45748 | O12: Junior Lopes | Q12: =G35 -> 15 | R12: =G36 -> 13 | S12: =G37 -> 11064.68 | T12: =G38 -> 13345.68 | U12: =G39 -> 124112.08 | V12: 150 | W12: 15 | X12: 12 | Y12: 10 | Z12: 30 | AA12: 90000 | AB12: =metas[[#This Row],[Meta Individual]]/10000 -> 1.106468 | AC12: =metas[[#This Row],[Meta Equipe]]/30000/3 -> 0.14828533
A13: RAYSSA | E13: JUNIOR | I13: PAULO | M13: 2025 | N13: 45748 | O13: Paulo Souza | Q13: =K35 -> 5 | R13: =K36 -> 6 | S13: =K37 -> 2088 | T13: =K38 -> 13345.68 | U13: =K39 -> 32058 | V13: 150 | W13: 15 | X13: 12 | Y13: 10 | Z13: 30 | AA13: 90000 | AB13: =metas[[#This Row],[Meta Individual]]/10000 -> 0.2088 | AC13: =metas[[#This Row],[Meta Equipe]]/30000/3 -> 0.14828533
B14: Meta | C14: Realizado | D14: Cobertura | F14: Meta | G14: Realizado | H14: Cobertura | J14: Meta | K14: Realizado | L14: Cobertura | M14: 2025 | N14: 45778 | O14: Rayssa Karapeticov | Q14: =C45 -> 23 | R14: =C46 -> 20 | S14: =C47 -> Realizado | T14: =C48 -> 23 | U14: =C49 -> 20 | V14: 150 | W14: 15 | X14: 12 | Y14: 10 | Z14: 30 | AA14: 90000 | AB14: =metas[[#This Row],[Meta Individual]]/10000 -> #VALUE! | AC14: =metas[[#This Row],[Meta Equipe]]/30000/3 -> 0.00025555556
A15: Proposta | B15: 15 | C15: 23 | D15: 1.5333333 | E15: Proposta | F15: 15 | G15: 16 | H15: 1.0666667 | I15: Proposta | J15: 15 | K15: 9 | L15: 0.6 | M15: 2025 | N15: 45778 | O15: Junior Lopes | Q15: =G45 -> 17 | R15: =G46 -> 14 | S15: =G47 -> Realizado | T15: =G48 -> 17 | U15: =G49 -> 14 | V15: 150 | W15: 15 | X15: 12 | Y15: 10 | Z15: 30 | AA15: 90000 | AB15: =metas[[#This Row],[Meta Individual]]/10000 -> #VALUE! | AC15: =metas[[#This Row],[Meta Equipe]]/30000/3 -> 0.00018888889
A16: Apresentações | B16: 12 | C16: 22 | D16: 1.8333333 | E16: Apresentações | F16: 12 | G16: 16 | H16: 1.3333333 | I16: Apresentações | J16: 12 | K16: 21 | L16: 1.75 | M16: 2025 | N16: 45778 | O16: Paulo Souza | Q16: =K45 -> 2 | R16: =K46 -> 1 | S16: =K47 -> Realizado | T16: =K48 -> 2 | U16: =K49 -> 1 | V16: 150 | W16: 15 | X16: 12 | Y16: 10 | Z16: 30 | AA16: 90000 | AB16: =metas[[#This Row],[Meta Individual]]/10000 -> #VALUE! | AC16: =metas[[#This Row],[Meta Equipe]]/30000/3 -> 2.2222222e-05
A17: Meta Individual | B17: 10000 | C17: 1288.03 | D17: 0.128803 | E17: Meta Individual | F17: 10000 | G17: 11189.93 | H17: 1.118993 | I17: Meta Individual | J17: 10000 | K17: 2087.44 | L17: 0.208744 | M17: 2025 | N17: 45809 | O17: Rayssa Karapeticov | Q17: =C55 -> 25 | R17: =C56 -> 19 | S17: =C57 -> 4260.96 | T17: =C58 -> 30275.77 | U17: =C59 -> 85918.58 | V17: 150 | W17: 15 | X17: 12 | Y17: 10 | Z17: 30 | AA17: 90000 | AB17: =metas[[#This Row],[Meta Individual]]/10000 -> 0.426096 | AC17: =metas[[#This Row],[Meta Equipe]]/30000/3 -> 0.33639744
A18: Meta Equipe | B18: 30000 | C18: 14565.4 | D18: 0.48551333 | E18: Meta Equipe | F18: 30000 | G18: 14565.4 | H18: 0.48551333 | I18: Meta Equipe | J18: 30000 | K18: 14565.4 | L18: 0.48551333 | M18: 2025 | N18: 45809 | O18: Junior Lopes | Q18: =G55 -> 18 | R18: =G56 -> 13 | S18: =G57 -> 4579.8 | T18: =G58 -> 30275.77 | U18: =G59 -> 33826.34 | V18: 150 | W18: 15 | X18: 12 | Y18: 10 | Z18: 30 | AA18: 90000 | AB18: =metas[[#This Row],[Meta Individual]]/10000 -> 0.45798 | AC18: =metas[[#This Row],[Meta Equipe]]/30000/3 -> 0.33639744
A19: Meta Projetos | B19: 90000 | C19: 85015.22 | D19: 0.94461356 | E19: Meta Projetos | F19: 90000 | G19: 121887.86 | H19: 1.3543096 | I19: Meta Projetos | J19: 90000 | K19: 19104 | L19: 0.21226667 | M19: 2025 | N19: 45809 | O19: Paulo Souza | Q19: =K55 -> 3 | R19: =K56 -> 1 | S19: =K57 -> 21435.01 | T19: =K58 -> 30275.77 | U19: =K59 -> 211246 | V19: 150 | W19: 15 | X19: 12 | Y19: 10 | Z19: 30 | AA19: 90000 | AB19: =metas[[#This Row],[Meta Individual]]/10000 -> 2.143501 | AC19: =metas[[#This Row],[Meta Equipe]]/30000/3 -> 0.33639744
M20: 2025 | N20: 45839 | O20: Rayssa Karapeticov | Q20: =C65 -> 22 | R20: =C66 -> 14 | S20: =C67 -> 1733.34 | T20: =C68 -> 11875.9 | U20: =C69 -> 86932.5 | V20: 150 | W20: 15 | X20: 12 | Y20: 10 | Z20: 30 | AA20: 90000 | AB20: =metas[[#This Row],[Meta Individual]]/10000 -> 0.173334 | AC20: =metas[[#This Row],[Meta Equipe]]/30000/3 -> 0.13195444
A21: FECHAMENTO DE: 01/03/2025 até 31/03/2025 | M21: 2025 | N21: 45839 | O21: Junior Lopes | Q21: =G65 -> 17 | R21: =G66 -> 12 | S21: =G67 -> 142.56 | T21: =G68 -> 11875.9 | U21: =G69 -> 6071.21 | V21: 150 | W21: 15 | X21: 12 | Y21: 10 | Z21: 30 | AA21: 90000 | AB21: =metas[[#This Row],[Meta Individual]]/10000 -> 0.014256 | AC21: =metas[[#This Row],[Meta Equipe]]/30000/3 -> 0.13195444
A22: COBERTURA DE METAS | M22: 2025 | N22: 45839 | O22: Paulo Souza | Q22: =K65 -> 2 | R22: =K66 -> 1 | S22: =K67 -> 10000 | T22: =K68 -> 11875.9 | U22: =K69 -> 90575 | V22: 150 | W22: 15 | X22: 12 | Y22: 10 | Z22: 30 | AA22: 90000 | AB22: =metas[[#This Row],[Meta Individual]]/10000 -> 1 | AC22: =metas[[#This Row],[Meta Equipe]]/30000/3 -> 0.13195444
A23: RAYSSA | E23: JUNIOR | I23: PAULO | M23: 2025 | N23: 45870 | O23: Rayssa Karapeticov | Q23: =C75 -> 25 | R23: =C76 -> 17 | S23: =C77 -> 1667.4 | T23: =C78 -> 14580.27 | U23: =C79 -> 37218.92 | V23: 150 | W23: 15 | X23: 12 | Y23: 10 | Z23: 30 | AA23: 90000 | AB23: =metas[[#This Row],[Meta Individual]]/10000 -> 0.16674 | AC23: =metas[[#This Row],[Meta Equipe]]/30000/3 -> 0.162003
B24: Meta | C24: Realizado | D24: Cobertura | F24: Meta | G24: Realizado | H24: Cobertura | J24: Meta | K24: Realizado | L24: Cobertura | M24: 2025 | N24: 45870 | O24: Junior Lopes | Q24: =G75 -> 16 | R24: =G76 -> 13 | S24: =G77 -> 5551.4 | T24: =G78 -> 14580.27 | U24: =G79 -> 69366.4 | V24: 150 | W24: 15 | X24: 12 | Y24: 10 | Z24: 30 | AA24: 90000 | AB24: =metas[[#This Row],[Meta Individual]]/10000 -> 0.55514 | AC24: =metas[[#This Row],[Meta Equipe]]/30000/3 -> 0.162003
A25: Proposta | B25: 15 | C25: 17 | D25: 1.1333333 | E25: Proposta | F25: 15 | G25: 17 | H25: 1.1333333 | I25: Proposta | J25: 15 | K25: 4 | L25: 0.26666667 | M25: 2025 | N25: 45870 | O25: Paulo Souza | Q25: =K75 -> 8 | R25: =K76 -> 8 | S25: =K77 -> 7361.47 | T25: =K78 -> 14580.27 | U25: =K79 -> 57100 | V25: 150 | W25: 15 | X25: 12 | Y25: 10 | Z25: 30 | AA25: 90000 | AB25: =metas[[#This Row],[Meta Individual]]/10000 -> 0.736147 | AC25: =metas[[#This Row],[Meta Equipe]]/30000/3 -> 0.162003
A26: Apresentações | B26: 12 | C26: 7 | D26: 0.58333333 | E26: Apresentações | F26: 12 | G26: 12 | H26: 1 | I26: Apresentações | J26: 12 | K26: 4 | L26: 0.33333333 | M26: 2025 | N26: 45901 | O26: Rayssa Karapeticov | Q26: =C85 -> 25 | R26: =C86 -> 16 | S26: =C87 -> 3619.87 | T26: =C88 -> 12925.19 | U26: =C89 -> 156911.7 | V26: 150 | W26: 15 | X26: 12 | Y26: 10 | Z26: 30 | AA26: 90000 | AB26: =metas[[#This Row],[Meta Individual]]/10000 -> 0.361987 | AC26: =metas[[#This Row],[Meta Equipe]]/30000/3 -> 0.14361322
A27: Meta Individual | B27: 10000 | C27: 6712.41 | D27: 0.671241 | E27: Meta Individual | F27: 10000 | G27: 3064.57 | H27: 0.306457 | I27: Meta Individual | J27: 10000 | K27: 5124.72 | L27: 0.512472 | M27: 2025 | N27: 45901 | O27: Junior Lopes | Q27: =G85 -> 16 | R27: =G86 -> 18 | S27: =G87 -> 6448.22 | T27: =G88 -> 12925.19 | U27: =G89 -> 134306.46 | V27: 150 | W27: 15 | X27: 12 | Y27: 10 | Z27: 30 | AA27: 90000 | AB27: =metas[[#This Row],[Meta Individual]]/10000 -> 0.644822 | AC27: =metas[[#This Row],[Meta Equipe]]/30000/3 -> 0.14361322
A28: Meta Equipe | B28: 30000 | C28: 14901.7 | D28: 0.49672333 | E28: Meta Equipe | F28: 30000 | G28: 14901.7 | H28: 0.49672333 | I28: Meta Equipe | J28: 30000 | K28: 14901.7 | L28: 0.49672333 | M28: 2025 | N28: 45901 | O28: Paulo Souza | Q28: =K85 -> 11 | R28: =K86 -> 11 | S28: =K87 -> 2857.1 | T28: =K88 -> 12925.19 | U28: =K89 -> 47500 | V28: 150 | W28: 15 | X28: 12 | Y28: 10 | Z28: 30 | AA28: 90000 | AB28: =metas[[#This Row],[Meta Individual]]/10000 -> 0.28571 | AC28: =metas[[#This Row],[Meta Equipe]]/30000/3 -> 0.14361322
A29: Meta Projetos | B29: 90000 | C29: 111207.36 | D29: 1.2356373 | E29: Meta Projetos | F29: 90000 | G29: 70833.33 | H29: 0.787037 | I29: Meta Projetos | J29: 90000 | K29: 73632 | L29: 0.81813333 | M29: 2025 | N29: 45931 | O29: Rayssa Karapeticov | Q29: =C95 -> 15 | R29: =C96 -> 12 | S29: =C97 -> 1927.89 | T29: =C98 -> 1927.89 | U29: =C99 -> 117851.89 | V29: 150 | W29: 15 | X29: 12 | Y29: 10 | Z29: 30 | AA29: 90000 | AB29: =metas[[#This Row],[Meta Individual]]/10000 -> 0.192789 | AC29: =metas[[#This Row],[Meta Equipe]]/30000/3 -> 0.021421
M30: 2025 | N30: 45931 | O30: Junior Lopes | Q30: =G95 -> 15 | R30: =G96 -> 12 | S30: =G97 -> 0 | T30: =G98 -> 1927.89 | U30: =G99 -> 39131.15 | V30: 150 | W30: 15 | X30: 12 | Y30: 10 | Z30: 30 | AA30: 90000 | AB30: =metas[[#This Row],[Meta Individual]]/10000 -> 0 | AC30: =metas[[#This Row],[Meta Equipe]]/30000/3 -> 0.021421
A31: FECHAMENTO DE: 01/04/2025 até 30/04/2025 | M31: 2025 | N31: 45931 | O31: Paulo Souza | Q31: =K95 -> 15 | R31: =K96 -> 12 | S31: =K97 -> 0 | T31: =K98 -> 1927.89 | U31: =K99 -> 0 | V31: 150 | W31: 15 | X31: 12 | Y31: 10 | Z31: 30 | AA31: 90000 | AB31: =metas[[#This Row],[Meta Individual]]/10000 -> 0 | AC31: =metas[[#This Row],[Meta Equipe]]/30000/3 -> 0.021421
A32: COBERTURA DE METAS | M32: 2025 | N32: 45962 | O32: Rayssa Karapeticov | Q32: =C105 -> 20 | R32: =C106 -> 18 | S32: =C107 -> 285.12 | T32: =C108 -> 641.52 | U32: =C109 -> 49993.72 | V32: 150 | W32: 15 | X32: 12 | Y32: 10 | Z32: 30 | AA32: 90000 | AB32: =metas[[#This Row],[Meta Individual]]/10000 -> 0.028512 | AC32: =metas[[#This Row],[Meta Equipe]]/30000/3 -> 0.007128
A33: RAYSSA | E33: JUNIOR | I33: PAULO | M33: 2025 | N33: 45962 | O33: Junior Lopes | Q33: =G105 -> 15 | R33: =G106 -> 13 | S33: =G107 -> 356.4 | T33: =G108 -> 641.52 | U33: =G109 -> 3307.14 | V33: 150 | W33: 15 | X33: 12 | Y33: 10 | Z33: 30 | AA33: 90000 | AB33: =metas[[#This Row],[Meta Individual]]/10000 -> 0.03564 | AC33: =metas[[#This Row],[Meta Equipe]]/30000/3 -> 0.007128
B34: Meta | C34: Realizado | D34: Cobertura | F34: Meta | G34: Realizado | H34: Cobertura | J34: Meta | K34: Realizado | L34: Cobertura | M34: 2025 | N34: 45962 | O34: Paulo Souza | Q34: =K105 -> 12 | R34: =K106 -> 12 | S34: =K108 -> 641.52 | T34: =K108 -> 641.52 | U34: =K109 -> 6253 | V34: 150 | W34: 15 | X34: 12 | Y34: 10 | Z34: 30 | AA34: 90000 | AB34: =metas[[#This Row],[Meta Individual]]/10000 -> 0.064152 | AC34: =metas[[#This Row],[Meta Equipe]]/30000/3 -> 0.007128
A35: Proposta | B35: 15 | C35: 29 | D35: 1.9333333 | E35: Proposta | F35: 15 | G35: 15 | H35: 1 | I35: Proposta | J35: 15 | K35: 5 | L35: 0.33333333 | M35: 2025 | N35: 45992 | O35: Rayssa Karapeticov | Q35: 10 | R35: 8 | S35: 3149.32 | T35: 10160.04 | U35: 97189.92 | V35: 150 | W35: 15 | X35: 12 | Y35: 6 | Z35: 26 | AA35: 90000 | AB35: =metas[[#This Row],[Meta Individual]]/6000 -> 0.52488667 | AC35: =metas[[#This Row],[Meta Equipe]]/26000/3 -> 0.13025692
A36: Apresentações | B36: 12 | C36: 15 | D36: 1.25 | E36: Apresentações | F36: 12 | G36: 13 | H36: 1.0833333 | I36: Apresentações | J36: 12 | K36: 6 | L36: 0.5 | M36: 2025 | N36: 45992 | O36: Junior Lopes | Q36: 10 | R36: 11 | S36: 6440.48 | T36: 10160.04 | U36: 38960 | V36: 150 | W36: 15 | X36: 12 | Y36: 10 | Z36: 26 | AA36: 90000 | AB36: =metas[[#This Row],[Meta Individual]]/10000 -> 0.644048 | AC36: =metas[[#This Row],[Meta Equipe]]/26000/3 -> 0.13025692
A37: Meta Individual | B37: 10000 | C37: 193 | D37: 0.0193 | E37: Meta Individual | F37: 10000 | G37: 11064.68 | H37: 1.106468 | I37: Meta Individual | J37: 10000 | K37: 2088 | L37: 0.2088 | M37: 2025 | N37: 45992 | O37: Paulo Souza | Q37: 8 | R37: 8 | S37: 570.24 | T37: 10160.04 | U37: =K112 -> 0 | V37: 150 | W37: 15 | X37: 12 | Y37: 10 | Z37: 26 | AA37: 90000 | AB37: =metas[[#This Row],[Meta Individual]]/10000 -> 0.057024 | AC37: =metas[[#This Row],[Meta Equipe]]/26000/3 -> 0.13025692
A38: Meta Equipe | B38: 30000 | C38: 13345.68 | D38: 0.444856 | E38: Meta Equipe | F38: 30000 | G38: 13345.68 | H38: 0.444856 | I38: Meta Equipe | J38: 30000 | K38: 13345.68 | L38: 0.444856 | M38: 2026 | N38: 46023 | O38: Rayssa Karapeticov | Q38: 24 | R38: 16 | S38: 2698.22 | T38: 17506.46 | U38: 58587.27 | V38: 150 | W38: 15 | X38: 12 | Y38: 6 | Z38: 26 | AA38: 90000 | AB38: =metas[[#This Row],[Meta Individual]]/6000 -> 0.44970333 | AC38: =metas[[#This Row],[Meta Equipe]]/26000/3 -> 0.22444179
A39: Meta Projetos | B39: 90000 | C39: 29258.82 | D39: 0.325098 | E39: Meta Projetos | F39: 90000 | G39: 124112.08 | H39: 1.3790231 | I39: Meta Projetos | J39: 90000 | K39: 32058 | L39: 0.3562 | M39: 2026 | N39: 46023 | O39: Junior Lopes | Q39: 16 | R39: 16 | S39: 4434.5 | T39: 17506.46 | U39: 101301 | V39: 150 | W39: 15 | X39: 12 | Y39: 10 | Z39: 26 | AA39: 90000 | AB39: =metas[[#This Row],[Meta Individual]]/10000 -> 0.44345 | AC39: =metas[[#This Row],[Meta Equipe]]/26000/3 -> 0.22444179
M40: 2026 | N40: 46023 | O40: Paulo Souza | Q40: 10 | R40: 10 | S40: 10373.74 | T40: 17506.46 | U40: 97790.97 | V40: 150 | W40: 15 | X40: 12 | Y40: 10 | Z40: 26 | AA40: 90000 | AB40: =metas[[#This Row],[Meta Individual]]/10000 -> 1.037374 | AC40: =metas[[#This Row],[Meta Equipe]]/26000/3 -> 0.22444179
...

Sheet KPI
A2: RAYSSA KARAPETICOV
D18: COBERTURA METAS | H18: COBERTURA METAS EQUIPES | N18: APRESENTAÇÃO RAYSSA | Q18: APRESENTAÇÃO JUNIOR LOPES | T18: APRESENTAÇÃO PAULO | W18: APRESENTAÇÃO RONALDO | AA18: APRESENTAÇÃO BASE RAYSSA | AD18: APRESENTAÇÃO BASE PAULO
D19: Vendedor | E19: Rayssa Karapeticov | H19: Ano | I19: (Vários itens) | N19: Responsável | O19: Rayssa Karapeticov | Q19: Responsável | R19: Junior Lopes | T19: Responsável | U19: Paulo Souza | W19: Responsável | X19: Ronaldo Nascimento | AA19: Responsável | AB19: Rayssa Karapeticov | AD19: Responsável | AE19: Paulo Souza
D20: Ano | E20: (Vários itens) | H20: Vendedor | I20: (Tudo) | N20: DataApresentação1 | O20: (Vários itens) | Q20: DataApresentação1 | R20: (Vários itens) | T20: DataApresentação1 | U20: (Vários itens) | W20: DataApresentação1 | X20: (Vários itens) | AA20: DataApresentação1 | AB20: (Vários itens) | AD20: DataApresentação1 | AE20: (Vários itens)
D22: Rótulos de Linha | E22: Cobertura | F22: Objetivo | H22: Rótulos de Linha | I22: Cobertura | J22: Objetivo | N22: Rótulos de Linha | O22: Soma de qtde | Q22: Rótulos de Linha | R22: Soma de QTDE | T22: Rótulos de Linha | U22: Soma de QTDE | W22: Rótulos de Linha | X22: Soma de qtde | AA22: Rótulos de Linha | AB22: Soma de Qdte | AD22: Rótulos de Linha | AE22: Soma de Qdte
D23: jan | E23: 0.44970333 | F23: 6 | H23: jan | I23: 0.67332538 | J23: 78 | N23: max led | O23: 1 | Q23: startools ferramentas, comercio, importacao e exportacao ltda | R23: 1 | T23: Total Geral | W23: estilo ar | X23: 1 | AA23: Mta Panelas | AB23: 1 | AD23: Total Geral
D24: fev | E24: 0.37133538 | F24: 6.5 | H24: fev | I24: 2.7055294 | J24: 79.5 | N24: Total Geral | O24: 1 | Q24: encartelados nina - erp | R24: 1 | W24: fikssar distribuidora | X24: 1 | AA24: Campeao | AB24: 1
D25: mar | E25: 0.91789714 | F25: 7 | H25: mar | I25: 0.85241407 | J25: 81 | Q25: encartelados nina - cloud | R25: 1 | W25: marden medical | X25: 1 | AA25: QUALITY HOUSE - WMS | AB25: 1
D26: abr | E26: 0.358848 | F26: 7.5 | H26: abr | I26: 0.56714945 | J26: 82.5 | Q26: tecelagem castilho (e-commerce) | R26: 1 | W26: Total Geral | X26: 3 | AA26: SUTT IMPORTADORA - Cloud | AB26: 1
D27: mai | E27: 0.14790625 | F27: 8 | H27: mai | I27: 0.27155794 | J27: 136 | Q27: istok comercio importacao (erp) | R27: 1 | AA27: Univendas - BI | AB27: 1
D28: Total Geral | E28: 2.2456901 | F28: 35 | H28: Total Geral | I28: 5.0699763 | J28: 457 | Q28: istok comercio importação (cloud) | R28: 1 | AA28: SHOCK IMPORTS - Tray | AB28: 1
Q29: startools ferramentas (erp) | R29: 1 | AA29: Total Geral | AB29: 6
Q30: mdl - boleto whats | R30: 1
Q31: star distribuidora - boleto whats | R31: 1
Q32: Total Geral | R32: 9
N1330: PROPOSTA RAYSSA | Q1330: PROPOSTA JUNIOR LOPES | T1330: PROPOSTA PAULO | W1330: PROPOSTA RONALDO | AA1330: PROPOSTA RAYSSA | AD1330: PROPOSTA PAULO
N1331: Responsável | O1331: Rayssa Karapeticov | Q1331: Responsável | R1331: Junior Lopes | T1331: Responsável | U1331: Paulo Souza | W1331: Responsável | X1331: Ronaldo Nascimento | AA1331: Responsável | AB1331: Rayssa Karapeticov | AD1331: Responsável | AE1331: Paulo Souza
N1332: Data Proposta | O1332: (Vários itens) | Q1332: Data Proposta | R1332: (Vários itens) | T1332: Data Proposta | U1332: (Vários itens) | W1332: Data Proposta | X1332: (Vários itens) | AA1332: Data Proposta | AB1332: (Vários itens) | AD1332: Data Proposta | AE1332: (Vários itens)
N1334: Rótulos de Linha | O1334: Soma de QTDE | Q1334: Rótulos de Linha | R1334: Soma de QTDE | T1334: Rótulos de Linha | U1334: Soma de QTDE | W1334: Rótulos de Linha | X1334: Soma de qtde | AA1334: Rótulos de Linha | AB1334: Soma de Qdte | AD1334: Rótulos de Linha | AE1334: Soma de Qdte
N1335: simao distribuidora | O1335: 1 | Q1335: encartelados nina - erp | R1335: 1 | T1335: hober artefatos plasticos ltda | U1335: 1 | W1335: fikssar distribuidora | X1335: 1 | AA1335: Campeao | AB1335: 1 | AD1335: Total Geral
N1336: fernandopolis industria e comercio de piscinas e acessorios ltda | O1336: 1 | Q1336: encartelados nina - cloud | R1336: 1 | T1336: Total Geral | U1336: 1 | W1336: Total Geral | X1336: 1 | AA1336: Mta Panelas | AB1336: 1
N1337: Total Geral | O1337: 2 | Q1337: mdl (horas) | R1337: 1 | AA1337: QUALITY HOUSE - WMS | AB1337: 1
Q1338: istok comercio importacao (erp) | R1338: 1 | AA1338: SUTT IMPORTADORA - Cloud | AB1338: 1
Q1339: istok comercio importação (cloud) | R1339: 1 | AA1339: Univendas - BI | AB1339: 1
Q1340: baag - horas | R1340: 1 | AA1340: Precisa Import - Power BI | AB1340: 1
Q1341: mdl - comex | R1341: 1 | AA1341: SHOCK IMPORTS - Tray | AB1341: 1
Q1342: mdl - boleto whats | R1342: 1 | AA1342: Total Geral | AB1342: 7
Q1343: star distribuidora - boleto whats | R1343: 1
Q1344: Total Geral | R1344: 9

Sheet Forecast
A1: Qtde | B1: Cliente | C1: Produto | D1: Responsável | E1: Vlr Projeto | F1: Mensalidade | G1: Horas | H1: Pipeline | I1: Temperatura
A2: 1 | B2: Porto Brasil Cerâmica – AFV | C2: AFV | D2: Junior Lopes | E2: 33920 | F2: 3768 | G2: 160 | H2: Vendas | I2: 0.5
A3: 1 | B3: Renovação Porcelanas – AFV | C3: AFV | D3: Junior Lopes | E3: 55713 | F3: 6391 | G3: 292 | H3: Vendas | I3: 0.3
A4: 1 | B4: Tiago Eletrônicos – B2B | C4: B2B | D4: Junior Lopes | E4: 26200 | F4: 3000 | G4: 80 | H4: Vendas | I4: 0.9
A5: 1 | B5: Amilplast Ind – ERP | C5: ERP | D5: Junior Lopes | E5: 51300 | F5: 1734 | G5: 270 | H5: Vendas | I5: 0.9
A6: 1 | B6: MDL Import – Cloud | C6: CLOUD | D6: Junior Lopes | E6: 1600 | F6: 2568 | G6: 16 | H6: Vendas | I6: 0.8
A7: 1 | B7: Plasbrink Embalagens Plásticas Ltda – ERP | C7: ERP | D7: Junior Lopes | E7: 81786 | F7: 7965 | G7: 430 | H7: Vendas | I7: 0.5
A8: 1 | B8: Plasbrink Embalagens Plásticas Ltda – Cloud | C8: CLOUD | D8: Junior Lopes | E8: 1600 | F8: 3356 | G8: 16 | H8: Vendas | I8: 0.5
A9: 1 | B9: Preciza Import – Boleto WhatsApp | C9: ADDON BOLETO WHATSAPP | D9: Junior Lopes | E9: 0 | F9: 356.4 | G9: 0 | H9: Vendas | I9: 0.5
A10: 1 | B10: Marka Têxtil – ERP | C10: ERP | D10: Junior Lopes | E10: 118908 | F10: 13048 | G10: 540 | H10: Vendas | I10: 0.8
A11: 1 | B11: Marka Têxtil – Cloud | C11: CLOUD | D11: Junior Lopes | E11: 1600 | F11: 6846 | G11: 16 | H11: Vendas | I11: 0.8
A12: 1 | B12: Sevilla Trade – ERP | C12: ERP | D12: Junior Lopes | E12: 38380 | F12: 1075 | G12: 190 | H12: Vendas | I12: 0.3
A13: 1 | B13: Sevilla Trade – Cloud | C13: CLOUD | D13: Junior Lopes | E13: 1600 | F13: 2174 | G13: 16 | H13: Vendas | I13: 0.3
... A18: 1 | B18: Conthey – ERP | C18: ERP | D18: Junior Lopes | E18: 72000 | F18: 4215 | G18: 360 | H18: Vendas | I18: 0.5
A19: 1 | B19: Conthey – AFV | C19: AFV | D19: Junior Lopes | E19: =40*180 -> 7200 | F19: 1964.2 | G19: 8 | H19: Vendas | I19: 0.5
A20: 1 | B20: Conthey – Cloud | C20: CLOUD | D20: Junior Lopes | E20: 1600 | F20: 5242 | G20: 16 | H20: Vendas | I20: 0.5
A21: 1 | B21: Star – B2B | C21: B2B | D21: Junior Lopes | E21: 26200 | F21: 3400 | G21: 80 | H21: Vendas | I21: 0.3
A22: 1 | B22: Erca Alumínio – Imp. XML | C22: ADDON IMPORTAÇÃO XML | D22: Junior Lopes | E22: 3392 | F22: 356.4 | G22: 16 | H22: Vendas | I22: 0.5
A23: 1 | B23: Toptem – ERP | C23: ERP | D23: Junior Lopes | E23: 44000 | F23: 1102 | G23: 220 | H23: Vendas | I23: 0.3
A24: 1 | B24: Toptem – AFV | C24: AFV | D24: Junior Lopes | E24: 8000 | F24: 1865 | G24: 40 | H24: Vendas | I24: 0.3
A25: 1 | B25: Chavetas Comércio de Peças e Ferramentas Ltda | C25: QUALIFICANDO | D25: Junior Lopes | E25: apresentando | F25: apresentando | G25: apresentando | H25: Vendas | I25: 0.3
A26: 1 | B26: Color Unhas | C26: QUALIFICANDO | D26: Junior Lopes | E26: apresentando | F26: apresentando | G26: apresentando | H26: Vendas | I26: 0.3
A27: 1 | B27: Folha Dourada Tabacos Ltda | C27: QUALIFICANDO | D27: Junior Lopes | E27: apresentando | F27: apresentando | G27: apresentando | H27: Vendas | I27: 0.3
A28: 1 | B28: Atacadão Delfino | C28: QUALIFICANDO | D28: Junior Lopes | E28: qualificando | F28: qualificando | G28: qualificando | H28: Vendas | I28: 0.3
A29: 1 | B29: BK Comércio | C29: QUALIFICANDO | D29: Junior Lopes | E29: qualificando | F29: qualificando | G29: qualificando | H29: Vendas | I29: 0.3
A30: 1 | B30: Sunguider Importador/Distribuidor | C30: ERP | D30: Paulo Souza | E30: apresentando | F30: apresentando | G30: apresentando | H30: Vendas | I30: 0.5
A31: 1 | B31: Indústria Oyshi | C31: AFV | D31: Paulo Souza | E31: 16000 | F31: 1558 | G31: 80 | H31: Vendas | I31: 0.5
A32: 1 | B32: Alumínio Ramos | C32: ERP | D32: Paulo Souza | E32: 153599 | F32: 9247.44 | G32: 768 | H32: Vendas | I32: 0.3
A33: 1 | B33: Wellmix – ERP | C33: ERP | D33: Paulo Souza | E33: 254760 | F33: 15786 | G33: 1158 | H33: Vendas | I33: 0.3
A34: 1 | B34: Medihosp | C34: AFV | D34: Paulo Souza | E34: 20000 | F34: 5880 | G34: 80 | H34: Vendas | I34: 0.3
A35: 1 | B35: Bela Flor | C35: ERP, AFV, WMS | D35: Paulo Souza | E35: 130600 | F35: 16809 | G35: 653 | H35: Vendas | I35: 0.3
A36: 1 | B36: Imev Proteínas | C36: AFV | D36: Paulo Souza | E36: 16000 | F36: 5880 | G36: 80 | H36: Vendas | I36: 0.9
A37: 1 | B37: AIH Importadora de Artigos de Presentes Ltda | C37: ERP, AFV | D37: Paulo Souza | E37: 72000 | F37: 8045 | G37: 360 | H37: Vendas | I37: 0.3
A38: 1 | B38: Maia 4 | C38: ERP | D38: Paulo Souza | E38: apresentando | F38: apresentando | G38: apresentando | H38: Vendas | I38: 0.3
A39: 1 | B39: Zomax | C39: AFV | D39: Paulo Souza | E39: apresentando | F39: apresentando | G39: apresentando | H39: Vendas | I39: 0.3
A40: 1 | B40: Val Port | C40: ERP, PDV | D40: Paulo Souza | E40: apresentando | F40: apresentando | G40: apresentando | H40: Vendas | I40: 0.3
A41: 1 | B41: Tron | C41: ERP | D41: Paulo Souza | E41: 315000 | F41: 32575 | G41: 1500 | H41: Vendas | I41: 0.3
A42: 1 | B42: HF Utilidades | C42: ERP | D42: Paulo Souza | E42: 47200 | F42: 2298.1 | G42: 236 | H42: Vendas | I42: 0.3
A43: 1 | B43: Valport – B2B | C43: B2B | D43: Paulo Souza | E43: apresentando | F43: apresentando | G43: apresentando | H43: Vendas | I43: 0.3
A44: 1 | B44: Atual Mix | C44: ERP | D44: Paulo Souza | E44: apresentando | F44: apresentando | G44: apresentando | H44: Vendas | I44: 0.3
...

Sheet ||

Sheet KPI-Metas
A1: RELATÓTIO APURAÇÃO OBJETIVOS DE FEVEREIRO 2026 | Q1: =A1 -> RELATÓTIO APURAÇÃO OBJETIVOS DE FEVEREIRO 2026 | AH1: =Q1 -> RELATÓTIO APURAÇÃO OBJETIVOS DE FEVEREIRO 2026 | AY1: RELATÓTIO APURAÇÃO OBJETIVOS DE MARÇO 2026 | BO1: =AY1 -> RELATÓTIO APURAÇÃO OBJETIVOS DE MARÇO 2026 | CF1: =BO1 -> RELATÓTIO APURAÇÃO OBJETIVOS DE MARÇO 2026 | CW1: RELATÓTIO APURAÇÃO OBJETIVOS DE MARÇO 2026 | DM1: =CW1 -> RELATÓTIO APURAÇÃO OBJETIVOS DE MARÇO 2026 | ED1: =DM1 -> RELATÓTIO APURAÇÃO OBJETIVOS DE MARÇO 2026
A2: APURAÇÃO: 02/03/2026 | Q2: =A2 -> APURAÇÃO: 02/03/2026 | AH2: =Q2 -> APURAÇÃO: 02/03/2026 | AY2: APURAÇÃO: 02/04/2026 | BO2: =AY2 -> APURAÇÃO: 02/04/2026 | CF2: =BO2 -> APURAÇÃO: 02/04/2026 | CW2: APURAÇÃO: 03/05/2026 | DM2: =CW2 -> APURAÇÃO: 03/05/2026 | ED2: =DM2 -> APURAÇÃO: 03/05/2026
A3: PERÍODO: 01/02/2026 até 28/02/2026 | Q3: =A3 -> PERÍODO: 01/02/2026 até 28/02/2026 | AH3: =Q3 -> PERÍODO: 01/02/2026 até 28/02/2026 | AY3: PERÍODO: 01/03/2026 até 31/03/2026 | BO3: =AY3 -> PERÍODO: 01/03/2026 até 31/03/2026 | CF3: =BO3 -> PERÍODO: 01/03/2026 até 31/03/2026 | CW3: PERÍODO: 01/04/2026 até 30/04/2026 | DM3: =CW3 -> PERÍODO: 01/04/2026 até 30/04/2026 | ED3: =DM3 -> PERÍODO: 01/04/2026 até 30/04/2026
A5: RAYSSA | F5: VENDAS | W5: VENDAS | AH5: PAULO | AM5: VENDAS | AY5: RAYSSA | BD5: VENDAS | BO5: JUNIOR | BU5: VENDAS | CF5: PAULO | CK5: VENDAS | CW5: RAYSSA | DB5: VENDAS | DM5: JUNIOR | DS5: VENDAS | ED5: PAULO | EI5: VENDAS
B6: Meta | C6: Realizado | D6: Cobertura | F6: RAYSSA | J6: RAYSSA | R6: Meta | S6: Realizado | T6: Cobertura | W6: JUNIOR | AI6: Meta | AJ6: Realizado | AK6: Cobertura | AM6: PAULO | AZ6: Meta | BA6: Realizado | BB6: Cobertura | BD6: RAYSSA | BH6: RAYSSA | BP6: Meta | BQ6: Realizado | BR6: Cobertura | BU6: JUNIOR | CG6: Meta | CH6: Realizado | CI6: Cobertura | CK6: PAULO | CX6: Meta | CY6: Realizado | CZ6: Cobertura | DB6: RAYSSA | DF6: RAYSSA | DN6: Meta | DO6: Realizado | DP6: Cobertura | DS6: JUNIOR | EE6: Meta | EF6: Realizado | EG6: Cobertura | EI6: PAULO
A7: Proposta (15) | B7: 15 | C7: 26 | D7: =C7/B7 -> 1.7333333 | F7: Data | G7: Ticket | H7: Vendedor | I7: Cliente | J7: Produto | K7: TipoReceita | L7: Qtde | M7: VlrUnitário | N7: VlrTotal | O7: Vlr Meta | Q7: Proposta | R7: 15 | S7: 16 | T7: =S7/R7 -> 1.0666667 | W7: Data | X7: Ticket | Y7: Vendedor | Z7: Cliente | AA7: Produto | AB7: TipoReceita | AC7: Qtde | AD7: VlrUnitário | AE7: VlrTotal | AF7: Vlr Meta | AH7: Proposta | AI7: 15 | AJ7: 17 | AK7: =AJ7/AI7 -> 1.1333333 | AM7: Data | AN7: Ticket | AO7: Vendedor | AP7: Cliente | AQ7: Produto | AR7: TipoReceita | AS7: Qtde | AT7: VlrUnitário | AU7: VlrTotal | AV7: Vlr Meta | AY7: Proposta (15) | AZ7: 15 | BA7: 21 | BB7: =BA7/AZ7 -> 1.4 | BD7: Data | BE7: Ticket | BF7: Vendedor | BG7: Cliente | BH7: Produto | BI7: TipoReceita | BJ7: Qtde | BK7: VlrUnitário | BL7: VlrTotal | BM7: Vlr Meta | BO7: Proposta | BP7: 15 | BQ7: 18 | BR7: =BQ7/BP7 -> 1.2 | BU7: Data | BV7: Ticket | BW7: Vendedor | BX7: Cliente | BY7: Produto | BZ7: TipoReceita | CA7: Qtde | CB7: VlrUnitário | CC7: VlrTotal | CD7: Vlr Meta | CF7: Proposta | CG7: 15 | CH7: 7 | CI7: =CH7/CG7 -> 0.46666667 | CK7: Data | CL7: Ticket | CM7: Vendedor | CN7: Cliente | CO7: Produto | CP7: TipoReceita | CQ7: Qtde | CR7: VlrUnitário | CS7: VlrTotal | CT7: Vlr Meta | CW7: Proposta (15) | CX7: 15 | CY7: 9 | CZ7: =CY7/CX7 -> 0.6 | DB7: Data | DC7: Ticket | DD7: Vendedor | DE7: Cliente | DF7: Produto | DG7: TipoReceita | DH7: Qtde | DI7: VlrUnitário | DJ7: VlrTotal | DK7: Vlr Meta | DM7: Proposta | DN7: 15 | DO7: 7 | DP7: =DO7/DN7 -> 0.46666667 | DS7: Data | DT7: Ticket | DU7: Vendedor | DV7: Cliente | DW7: Produto | DX7: TipoReceita | DY7: Qtde | DZ7: VlrUnitário | EA7: VlrTotal | EB7: Vlr Meta | ED7: Proposta | EE7: 15 | EF7: 2 | EG7: =EF7/EE7 -> 0.13333333 | EI7: Data | EJ7: Ticket | EK7: Vendedor | EL7: Cliente | EM7: Produto | EN7: TipoReceita | EO7: Qtde | EP7: VlrUnitário | EQ7: VlrTotal | ER7: Vlr Meta
A8: Apresentações (12) | B8: 12 | C8: 31 | D8: =C8/B8 -> 2.5833333 | F8: 46059 | G8: 137739 | H8: Rayssa Karapeticov | I8: Textil Regimara | J8: BI | K8: CDU | L8: 1 | M8: 8100 | N8: 8100 | O8: 9720 | Q8: Apresentações | R8: 12 | S8: 13 | T8: =S8/R8 -> 1.0833333 | W8: 46055 | X8: 130904 | Y8: Junior Lopes | Z8: Tiago eletronicos | AA8: B2B | AB8: CDU | AC8: 1 | AD8: 22270 | AE8: 22270 | AF8: 22270 | AH8: Apresentações | AI8: 12 | AJ8: 15 | AK8: =AJ8/AI8 -> 1.25 | AM8: 46055 | AN8: 128860 | AO8: Paulo Souza | AP8: Sagol | AQ8: Treinamento | AR8: Treinamentos e Implantações | AS8: 110 | AT8: 185 | AU8: 20350 | AV8: 20350 | AY8: Apresentações (12) | AZ8: 12 | BA8: 16 | BB8: =BA8/AZ8 -> 1.3333333 | BD8: 46083 | BE8: 137844 | BF8: Rayssa Karapeticov | BG8: FWB | BH8: Melhoria | BI8: Melhoria | BJ8: 3 | BK8: 176 | BL8: 528 | BM8: 528 | BO8: Apresentações | BP8: 12 | BQ8: 16 | BR8: =BQ8/BP8 -> 1.3333333 | BU8: 46092 | BV8: 139463 | BW8: Junior Lopes | BX8: Clean Tech | BY8: ERP | BZ8: Treinamentos e Implantações | CA8: 340 | CB8: 171 | CC8: 58140 | CD8: 58140 | CF8: Apresentações | CG8: 12 | CH8: 6 | CI8: =CH8/CG8 -> 0.5 | CK8: Data | CL8: Ticket | CM8: Vendedor | CN8: Cliente | CO8: Produto | CP8: TipoReceita | CQ8: Qtde | CR8: VlrUnitário | CS8: VlrTotal | CT8: Vlr Meta | CW8: Apresentações (12) | CX8: 12 | CY8: 13 | CZ8: =CY8/CX8 -> 1.0833333 | DB8: 46119 | DC8: 138780 | DD8: Rayssa Karapeticov | DE8: MTA | DF8: Melhoria | DG8: Melhoria | DH8: 8 | DI8: 176 | DJ8: 1408 | DK8: 1408 | DM8: Apresentações | DN8: 12 | DO8: 7 | DP8: =DO8/DN8 -> 0.58333333 | DS8: 46113 | DT8: 138583 | DU8: Junior Lopes | DV8: Porto Brasil | DW8: AFV | DX8: CDU | DY8: 1 | DZ8: 24000 | EA8: 24000 | EB8: 24000 | ED8: Apresentações | EE8: 12 | EF8: 2 | EG8: =EF8/EE8 -> 0.16666667 | EI8: Data | EJ8: Ticket | EK8: Vendedor | EL8: Cliente | EM8: Produto | EN8: TipoReceita | EO8: Qtde | EP8: VlrUnitário | EQ8: VlrTotal | ER8: Vlr Meta
A9: Meta Individual (6,5k) | B9: 6500 | C9: 2413.68 | D9: =C9/B9 -> 0.37133538 | F9: 46059 | G9: 137739 | H9: Rayssa Karapeticov | I9: Textil Regimara | J9: BI | K9: Mensalidade | L9: 1 | M9: 1080 | N9: 1080 | O9: 1296 | Q9: Meta Individual | R9: 10000 | S9: 14107.5 | T9: =S9/R9 -> 1.41075 | W9: 46055 | X9: 130904 | Y9: Junior Lopes | Z9: Tiago eletronicos | AA9: B2B | AB9: Mensalidade | AC9: 1 | AD9: 3000 | AE9: 3000 | AF9: 3600 | AH9: Meta Individual | AI9: 10000 | AJ9: 55175.35 | AK9: =AJ9/AI9 -> 5.517535 | AM9: 46055 | AN9: 128860 | AO9: Paulo Souza | AP9: Sagol | AQ9: AFV | AR9: Mensalidade | AS9: 15 | AT9: 87 | AU9: 1305 | AV9: 1305 | AY9: Meta Individual (7k) | AZ9: 7000 | BA9: 6425.28 | BB9: =BA9/AZ9 -> 0.91789714 | BD9: 46083 | BE9: 138891 | BF9: Rayssa Karapeticov | BG9: Dasplast | BH9: MDe | BI9: Treinamentos e Implantações | BJ9: 8 | BK9: 210 | BL9: 1680 | BM9: 2016 | BO9: Meta Individual | BP9: 10000 | BQ9: 16288.54 | BR9: =BQ9/BP9 -> 1.628854 | BU9: 46092 | BV9: 139463 | BW9: Junior Lopes | BX9: Clean Tech | BY9: AFV | BZ9: Treinamentos e Implantações | CA9: 60 | CB9: 171 | CC9: 10260 | CD9: 10260 | CF9: Meta Individual | CG9: 10000 | CH9: 301.26 | CI9: =CH9/CG9 -> 0.030126 | CK9: 46092 | CL9: 128860 | CM9: Paulo Souza | CN9: Sagol | CO9: Treinamento | CP9: Treinamentos e Implantações | CQ9: 40 | CR9: 185 | CS9: 7400 | CT9: 7400 | CW9: Meta Individual (7k) | CX9: 7500 | CY9: 2691.36 | CZ9: =CY9/CX9 -> 0.358848 | DB9: 46119 | DC9: 138897 | DD9: Rayssa Karapeticov | DE9: Nixhouse | DF9: Melhoria | DG9: Melhoria | DH9: 64 | DI9: 156.25 | DJ9: 10000 | DK9: 10000 | DM9: Meta Individual | DN9: 10000 | DO9: 5224.65 | DP9: =DO9/DN9 -> 0.522465 | DS9: 46113 | DT9: 138583 | DU9: Junior Lopes | DV9: Porto Brasil | DW9: AFV | DX9: Treinamentos e Implantações | DY9: 100 | DZ9: 212 | EA9: 21200 | EB9: 21200 | ED9: Meta Individual | EE9: 10000 | EF9: 7680.6 | EG9: =EF9/EE9 -> 0.76806 | EI9: 46119 | EJ9: 138641 | EK9: Paulo Souza | EL9: Dinatale | EM9: WMS | EN9: Mensalidade | EO9: 10 | EP9: 142.56 | EQ9: 1425.6 | ER9: 1425.6
A10: Meta Equipe (26,5k) | B10: 26500 | C10: =C9+S9+AJ9 -> 71696.53 | D10: =C10/B10 -> 2.7055294 | F10: 46059 | G10: 137720 | H10: Rayssa Karapeticov | I10: Shock Import | J10: AFV | K10: Mensalidade | L10: 5 | M10: 115 | N10: 575 | O10: 690 | Q10: Meta Equipe | R10: 26500 | S10: =C10 -> 71696.53 | T10: =S10/R10 -> 2.7055294 | W10: 46059 | X10: 137190 | Y10: Junior Lopes | Z10: Conthey | AA10: ERP | AB10: Treinamentos e Implantações | AC10: 290 | AD10: 200 | AE10: 58000 | AF10: 58000 | AH10: Meta Equipe | AI10: 26500 | AJ10: =C10 -> 71696.53 | AK10: =AJ10/AI10 -> 2.7055294 | AM10: 46055 | AN10: 128860 | AO10: Paulo Souza | AP10: Sagol | AQ10: AFV Preposto | AR10: Mensalidade | AS10: 10 | AT10: 43.5 | AU10: 435 | AV10: 435 | AY10: Meta Equipe (26,5k) | AZ10: 27000 | BA10: =BA9+BQ9+CH9 -> 23015.08 | BB10: =BA10/AZ10 -> 0.85241037 | BD10: 46083 | BE10: 138891 | BF10: Rayssa Karapeticov | BG10: Dasplast | BH10: MDe | BI10: Mensalidade | BJ10: 1 | BK10: 356.4 | BL10: 356.4 | BM10: 427.68 | BO10: Meta Equipe | BP10: 27000 | BQ10: =BA10 -> 23015.08 | BR10: =BQ10/BP10 -> 0.85241037 | BU10: 46092 | BV10: 139463 | BW10: Junior Lopes | BX10: Clean Tech | BY10: WMS | BZ10: Treinamentos e Implantações | CA10: 48 | CB10: 171 | CC10: 0 | CD10: 0 | CF10: Meta Equipe | CG10: 27000 | CH10: =BA10 -> 23015.08 | CI10: =CH10/CG10 -> 0.85241037 | CK10: 46100 | CL10: 140072 | CM10: Paulo Souza | CN10: Rafinha Alimentos | CO10: Cloud Upgrade | CP10: Mensalidade | CQ10: 1 | CR10: 301.26 | CS10: 301.26 | CT10: 301.26 | CW10: Meta Equipe (26,5k) | CX10: 27500 | CY10: =CY9+DO9+EF9 -> 15596.61 | CZ10: =CY10/CX10 -> 0.56714945 | DB10: 46119 | DC10: 140964 | DD10: Rayssa Karapeticov | DE10: Rio Home | DF10: Znia | DG10: Treinamentos e Implantações | DH10: 16 | DI10: 210 | DJ10: 3360 | DK10: 4032 | DM10: Meta Equipe | DN10: 27000 | DO10: =CY10 -> 15596.61 | DP10: =DO10/DN10 -> 0.57765222 | DS10: 46113 | DT10: 138583 | DU10: Junior Lopes | DV10: Porto Brasil | DW10: AFV | DX10: Mensalidade | DY10: 61 | DZ10: 85.65 | EA10: 5224.65 | EB10: 5224.65 | ED10: Meta Equipe | EE10: 27000 | EF10: =CY10 -> 15596.61 | EG10: =EF10/EE10 -> 0.57765222 | EI10: 46120 | EJ10: 138614 | EK10: Paulo Souza | EL10: Dinatale | EM10: addon Loja B2B | EN10: Mensalidade | EO10: 60 | EP10: 19.25 | EQ10: 1155 | ER10: 1155
A11: Meta Projetos (90k) | B11: 90000 | C11: 96796.8 | D11: =C11/B11 -> 1.07552 | F11: 46059 | G11: 137481 | H11: Rayssa Karapeticov | I11: Kascao | J11: Treinamento | K11: Treinamentos e Implantações | L11: 8 | M11: 189 | N11: 1512 | O11: 1814.4 | Q11: Meta Projetos | R11: 90000 | S11: 97230 | T11: =S11/R11 -> 1.0803333 | W11: 46059 | X11: 137370 | Y11: Junior Lopes | Z11: Conthey | AA11: ERP | AB11: Mensalidade | AC11: 20 | AD11: 255 | AE11: 5100 | AF11: 5100 | AH11: Meta Projetos | AI11: 90000 | AJ11: 367161.6 | AK11: =AJ11/AI11 -> 4.0795733 | AM11: 46065 | AN11: 128860 | AO11: Paulo Souza | AP11: Sagol | AQ11: Envio Boleto Whatsapp | AR11: Mensalidade | AS11: 1 | AT11: 356.4 | AU11: 356.4 | AV11: 427.68 | AY11: Meta Projetos (90k) | AZ11: 90000 | BA11: 72913.14 | BB11: =BA11/AZ11 -> 0.810146 | BD11: 46092 | BE11: 134510 | BF11: Rayssa Karapeticov | BG11: Gyn | BH11: Treinamento | BI11: Treinamentos e Implantações | BJ11: 14 | BK11: 178.5 | BL11: 2499 | BM11: 2998.8 | BO11: Meta Projetos | BP11: 90000 | BQ11: 99854.09 | BR11: =BQ11/BP11 -> 1.1094899 | BU11: 46092 | BV11: 139465 | BW11: Junior Lopes | BX11: Clean Tech | BY11: Cloud | BZ11: Mensalidade | CA11: 1 | CB11: 3844.54 | CC11: 3844.54 | CD11: 3844.54 | CF11: Meta Projetos | CG11: 90000 | CH11: 7400 | CI11: =CH11/CG11 -> 0.082222222 | CK11: Total | CS11: 7701.26 | CT11: 7701.26 | CW11: Meta Projetos (90k) | CX11: 90000 | CY11: 55648 | CZ11: =CY11/CX11 -> 0.61831111 | DB11: 46119 | DC11: 140964 | DD11: Rayssa Karapeticov | DE11: Rio Home | DF11: Znia | DG11: Mensalidade | DH11: 1 | DI11: 712.8 | DJ11: 712.8 | DK11: 855.36 | DM11: Meta Projetos | DN11: 90000 | DO11: 45200 | DP11: =DO11/DN11 -> 0.50222222 | DS11: Total | EA11: =SUM(EA8:EA10) -> 50424.65 | EB11: =SUM(EB8:EB10) -> 50424.65 | ED11: Meta Projetos | EE11: 90000 | EF11: 38800.64 | EG11: =EF11/EE11 -> 0.43111822 | EI11: 46126 | EJ11: 125596 | EK11: Paulo Souza | EL11: Agua Sana | EM11: Treinamento | EN11: Treinamentos e Implantações | EO11: 43 | EP11: 169.78 | EQ11: 7300.54 | ER11: 7300.54
